Workbook

Sheet Read Me
B2: Clinical Evidence Library
B3: MPS IVA · MPS VI · CLN2 · Achondroplasia · PKU
B5: How to use
B6: 1. Library: one row per trial or reference. Pick the Product; generic name, therapy area, indication, company and Own/Competitor fill in by themselves.
B7: 2. Record Type says what the entry is: clinical trial, extension, natural history, real-world/registry, guideline, expert recommendation, review or internal material.
B8: 3. Pivotal = Yes marks the registration trials (they show in bold).
B9: 4. Year drives the timeline. Sort Year from smallest to largest for oldest to newest.
B10: 5. Confidentiality: rows from internal company documents are flagged in red. Don't share those externally.
B11: 6. Products: add competitor products in the empty rows before using them in the Library.
B13: Cell colours
B14: Yellow = you fill in
B15: Blue-grey = formula, fills in automatically. Don't type over these.
... B23: The Library sheet is an Excel table named 'Library', so it loads straight into Power BI (Get Data > Excel > Library).

Sheet Library
A1: Product | B1: Generic Name | C1: Therapy Area | D1: Indication | E1: Company | F1: Own / Competitor | G1: Record Type | H1: Title / Trial Name | I1: Study Code | J1: NCT Number | K1: Phase | L1: Pivotal | M1: Study Design | N1: Population | O1: Patients (N) | P1: Countries | Q1: Treatment / Dose | R1: Duration / Follow-up | S1: Primary Endpoint | T1: Other Endpoints | U1: Key Results | V1: Safety | W1: Status | X1: Start Date | Y1: Publication / Presentation Date | Z1: Year | AA1: Publication Reference | AB1: DOI / PMID | AC1: Key Takeaway | AD1: Source Document | AE1: Confidentiality | AF1: Notes | AG1: Last Verified
A2: Voxzogo | B2: =IF($A2="","",IFERROR(INDEX(Products!$B$2:$B$61,MATCH($A2,Products!$A$2:$A$61,0)),"Add to Products")) | C2: =IF($A2="","",IFERROR(INDEX(Products!$C$2:$C$61,MATCH($A2,Products!$A$2:$A$61,0)),"Add to Products")) | D2: =IF($A2="","",IFERROR(INDEX(Products!$D$2:$D$61,MATCH($A2,Products!$A$2:$A$61,0)),"Add to Products")) | E2: =IF($A2="","",IFERROR(INDEX(Products!$E$2:$E$61,MATCH($A2,Products!$A$2:$A$61,0)),"Add to Products")) | F2: =IF($A2="","",IFERROR(INDEX(Products!$F$2:$F$61,MATCH($A2,Products!$A$2:$A$61,0)),"Add to Products")) | G2: Clinical trial | H2: EXAMPLE ROW – replace with your own data | I2: 111-301 | K2: Phase 3 | L2: Yes | M2: Randomized, double-blind, placebo-controlled | N2: Children with achondroplasia, 5 to <18 years | O2: 121 | S2: Change in annualized growth velocity at week 52 | W2: Completed | Z2: 2020 | AE2: Public | AF2: Shows the expected format. Delete this row once you add real entries.
B3: =IF($A3="","",IFERROR(INDEX(Products!$B$2:$B$61,MATCH($A3,Products!$A$2:$A$61,0)),"Add to Products")) | C3: =IF($A3="","",IFERROR(INDEX(Products!$C$2:$C$61,MATCH($A3,Products!$A$2:$A$61,0)),"Add to Products")) | D3: =IF($A3="","",IFERROR(INDEX(Products!$D$2:$D$61,MATCH($A3,Products!$A$2:$A$61,0)),"Add to Products")) | E3: =IF($A3="","",IFERROR(INDEX(Products!$E$2:$E$61,MATCH($A3,Products!$A$2:$A$61,0)),"Add to Products")) | F3: =IF($A3="","",IFERROR(INDEX(Products!$F$2:$F$61,MATCH($A3,Products!$A$2:$A$61,0)),"Add to Products"))
B4: =IF($A4="","",IFERROR(INDEX(Products!$B$2:$B$61,MATCH($A4,Products!$A$2:$A$61,0)),"Add to Products")) | C4: =IF($A4="","",IFERROR(INDEX(Products!$C$2:$C$61,MATCH($A4,Products!$A$2:$A$61,0)),"Add to Products")) | D4: =IF($A4="","",IFERROR(INDEX(Products!$D$2:$D$61,MATCH($A4,Products!$A$2:$A$61,0)),"Add to Products")) | E4: =IF($A4="","",IFERROR(INDEX(Products!$E$2:$E$61,MATCH($A4,Products!$A$2:$A$61,0)),"Add to Products")) | F4: =IF($A4="","",IFERROR(INDEX(Products!$F$2:$F$61,MATCH($A4,Products!$A$2:$A$61,0)),"Add to Products"))
B5: =IF($A5="","",IFERROR(INDEX(Products!$B$2:$B$61,MATCH($A5,Products!$A$2:$A$61,0)),"Add to Products")) | C5: =IF($A5="","",IFERROR(INDEX(Products!$C$2:$C$61,MATCH($A5,Products!$A$2:$A$61,0)),"Add to Products")) | D5: =IF($A5="","",IFERROR(INDEX(Products!$D$2:$D$61,MATCH($A5,Products!$A$2:$A$61,0)),"Add to Products")) | E5: =IF($A5="","",IFERROR(INDEX(Products!$E$2:$E$61,MATCH($A5,Products!$A$2:$A$61,0)),"Add to Products")) | F5: =IF($A5="","",IFERROR(INDEX(Products!$F$2:$F$61,MATCH($A5,Products!$A$2:$A$61,0)),"Add to Products"))
B6: =IF($A6="","",IFERROR(INDEX(Products!$B$2:$B$61,MATCH($A6,Products!$A$2:$A$61,0)),"Add to Products")) | C6: =IF($A6="","",IFERROR(INDEX(Products!$C$2:$C$61,MATCH($A6,Products!$A$2:$A$61,0)),"Add to Products")) | D6: =IF($A6="","",IFERROR(INDEX(Products!$D$2:$D$61,MATCH($A6,Products!$A$2:$A$61,0)),"Add to Products")) | E6: =IF($A6="","",IFERROR(INDEX(Products!$E$2:$E$61,MATCH($A6,Products!$A$2:$A$61,0)),"Add to Products")) | F6: =IF($A6="","",IFERROR(INDEX(Products!$F$2:$F$61,MATCH($A6,Products!$A$2:$A$61,0)),"Add to Products"))
B7: =IF($A7="","",IFERROR(INDEX(Products!$B$2:$B$61,MATCH($A7,Products!$A$2:$A$61,0)),"Add to Products")) | C7: =IF($A7="","",IFERROR(INDEX(Products!$C$2:$C$61,MATCH($A7,Products!$A$2:$A$61,0)),"Add to Products")) | D7: =IF($A7="","",IFERROR(INDEX(Products!$D$2:$D$61,MATCH($A7,Products!$A$2:$A$61,0)),"Add to Products")) | E7: =IF($A7="","",IFERROR(INDEX(Products!$E$2:$E$61,MATCH($A7,Products!$A$2:$A$61,0)),"Add to Products")) | F7: =IF($A7="","",IFERROR(INDEX(Products!$F$2:$F$61,MATCH($A7,Products!$A$2:$A$61,0)),"Add to Products"))
B8: =IF($A8="","",IFERROR(INDEX(Products!$B$2:$B$61,MATCH($A8,Products!$A$2:$A$61,0)),"Add to Products")) | C8: =IF($A8="","",IFERROR(INDEX(Products!$C$2:$C$61,MATCH($A8,Products!$A$2:$A$61,0)),"Add to Products")) | D8: =IF($A8="","",IFERROR(INDEX(Products!$D$2:$D$61,MATCH($A8,Products!$A$2:$A$61,0)),"Add to Products")) | E8: =IF($A8="","",IFERROR(INDEX(Products!$E$2:$E$61,MATCH($A8,Products!$A$2:$A$61,0)),"Add to Products")) | F8: =IF($A8="","",IFERROR(INDEX(Products!$F$2:$F$61,MATCH($A8,Products!$A$2:$A$61,0)),"Add to Products"))
B9: =IF($A9="","",IFERROR(INDEX(Products!$B$2:$B$61,MATCH($A9,Products!$A$2:$A$61,0)),"Add to Products")) | C9: =IF($A9="","",IFERROR(INDEX(Products!$C$2:$C$61,MATCH($A9,Products!$A$2:$A$61,0)),"Add to Products")) | D9: =IF($A9="","",IFERROR(INDEX(Products!$D$2:$D$61,MATCH($A9,Products!$A$2:$A$61,0)),"Add to Products")) | E9: =IF($A9="","",IFERROR(INDEX(Products!$E$2:$E$61,MATCH($A9,Products!$A$2:$A$61,0)),"Add to Products")) | F9: =IF($A9="","",IFERROR(INDEX(Products!$F$2:$F$61,MATCH($A9,Products!$A$2:$A$61,0)),"Add to Products"))
B10: =IF($A10="","",IFERROR(INDEX(Products!$B$2:$B$61,MATCH($A10,Products!$A$2:$A$61,0)),"Add to Products")) | C10: =IF($A10="","",IFERROR(INDEX(Products!$C$2:$C$61,MATCH($A10,Products!$A$2:$A$61,0)),"Add to Products")) | D10: =IF($A10="","",IFERROR(INDEX(Products!$D$2:$D$61,MATCH($A10,Products!$A$2:$A$61,0)),"Add to Products")) | E10: =IF($A10="","",IFERROR(INDEX(Products!$E$2:$E$61,MATCH($A10,Products!$A$2:$A$61,0)),"Add to Products")) | F10: =IF($A10="","",IFERROR(INDEX(Products!$F$2:$F$61,MATCH($A10,Products!$A$2:$A$61,0)),"Add to Products"))
B11: =IF($A11="","",IFERROR(INDEX(Products!$B$2:$B$61,MATCH($A11,Products!$A$2:$A$61,0)),"Add to Products")) | C11: =IF($A11="","",IFERROR(INDEX(Products!$C$2:$C$61,MATCH($A11,Products!$A$2:$A$61,0)),"Add to Products")) | D11: =IF($A11="","",IFERROR(INDEX(Products!$D$2:$D$61,MATCH($A11,Products!$A$2:$A$61,0)),"Add to Products")) | E11: =IF($A11="","",IFERROR(INDEX(Products!$E$2:$E$61,MATCH($A11,Products!$A$2:$A$61,0)),"Add to Products")) | F11: =IF($A11="","",IFERROR(INDEX(Products!$F$2:$F$61,MATCH($A11,Products!$A$2:$A$61,0)),"Add to Products"))
B12: =IF($A12="","",IFERROR(INDEX(Products!$B$2:$B$61,MATCH($A12,Products!$A$2:$A$61,0)),"Add to Products")) | C12: =IF($A12="","",IFERROR(INDEX(Products!$C$2:$C$61,MATCH($A12,Products!$A$2:$A$61,0)),"Add to Products")) | D12: =IF($A12="","",IFERROR(INDEX(Products!$D$2:$D$61,MATCH($A12,Products!$A$2:$A$61,0)),"Add to Products")) | E12: =IF($A12="","",IFERROR(INDEX(Products!$E$2:$E$61,MATCH($A12,Products!$A$2:$A$61,0)),"Add to Products")) | F12: =IF($A12="","",IFERROR(INDEX(Products!$F$2:$F$61,MATCH($A12,Products!$A$2:$A$61,0)),"Add to Products"))
B13: =IF($A13="","",IFERROR(INDEX(Products!$B$2:$B$61,MATCH($A13,Products!$A$2:$A$61,0)),"Add to Products")) | C13: =IF($A13="","",IFERROR(INDEX(Products!$C$2:$C$61,MATCH($A13,Products!$A$2:$A$61,0)),"Add to Products")) | D13: =IF($A13="","",IFERROR(INDEX(Products!$D$2:$D$61,MATCH($A13,Products!$A$2:$A$61,0)),"Add to Products")) | E13: =IF($A13="","",IFERROR(INDEX(Products!$E$2:$E$61,MATCH($A13,Products!$A$2:$A$61,0)),"Add to Products")) | F13: =IF($A13="","",IFERROR(INDEX(Products!$F$2:$F$61,MATCH($A13,Products!$A$2:$A$61,0)),"Add to Products"))
B14: =IF($A14="","",IFERROR(INDEX(Products!$B$2:$B$61,MATCH($A14,Products!$A$2:$A$61,0)),"Add to Products")) | C14: =IF($A14="","",IFERROR(INDEX(Products!$C$2:$C$61,MATCH($A14,Products!$A$2:$A$61,0)),"Add to Products")) | D14: =IF($A14="","",IFERROR(INDEX(Products!$D$2:$D$61,MATCH($A14,Products!$A$2:$A$61,0)),"Add to Products")) | E14: =IF($A14="","",IFERROR(INDEX(Products!$E$2:$E$61,MATCH($A14,Products!$A$2:$A$61,0)),"Add to Products")) | F14: =IF($A14="","",IFERROR(INDEX(Products!$F$2:$F$61,MATCH($A14,Products!$A$2:$A$61,0)),"Add to Products"))
... B401: =IF($A401="","",IFERROR(INDEX(Products!$B$2:$B$61,MATCH($A401,Products!$A$2:$A$61,0)),"Add to Products")) | C401: =IF($A401="","",IFERROR(INDEX(Products!$C$2:$C$61,MATCH($A401,Products!$A$2:$A$61,0)),"Add to Products")) | D401: =IF($A401="","",IFERROR(INDEX(Products!$D$2:$D$61,MATCH($A401,Products!$A$2:$A$61,0)),"Add to Products")) | E401: =IF($A401="","",IFERROR(INDEX(Products!$E$2:$E$61,MATCH($A401,Products!$A$2:$A$61,0)),"Add to Products")) | F401: =IF($A401="","",IFERROR(INDEX(Products!$F$2:$F$61,MATCH($A401,Products!$A$2:$A$61,0)),"Add to Products"))

Sheet Summary
A1: Evidence Summary by Product
A2: Updates automatically from the Library sheet.
A4: Product | B4: Therapy Area | C4: Own / Competitor | D4: Total Records | E4: Pivotal Trials | F4: Clinical Trials | G4: Real-world / Registry | H4: Guidelines & Recommendations | I4: Internal / Confidential | J4: Earliest Year | K4: Latest Year
A5: =IF(Products!$A$2="","",Products!$A$2) | B5: =IF($A5="","",Products!$C$2) | C5: =IF($A5="","",Products!$F$2) | D5: =IF($A5="","",COUNTIFS(Library!$A$2:$A$401,$A5)) | E5: =IF($A5="","",COUNTIFS(Library!$A$2:$A$401,$A5,Library!$L$2:$L$401,"Yes")) | F5: =IF($A5="","",COUNTIFS(Library!$A$2:$A$401,$A5,Library!$G$2:$G$401,"Clinical trial")+COUNTIFS(Library!$A$2:$A$401,$A5,Library!$G$2:$G$401,"Extension study")) | G5: =IF($A5="","",COUNTIFS(Library!$A$2:$A$401,$A5,Library!$G$2:$G$401,"Registry / Real-world study")+COUNTIFS(Library!$A$2:$A$401,$A5,Library!$G$2:$G$401,"Natural history study")) | H5: =IF($A5="","",COUNTIFS(Library!$A$2:$A$401,$A5,Library!$G$2:$G$401,"Guideline / Consensus")+COUNTIFS(Library!$A$2:$A$401,$A5,Library!$G$2:$G$401,"Expert recommendation")) | I5: =IF($A5="","",COUNTIFS(Library!$A$2:$A$401,$A5,Library!$AE$2:$AE$401,"Internal use only")+COUNTIFS(Library!$A$2:$A$401,$A5,Library!$AE$2:$AE$401,"Confidential")) | J5: =IF($A5="","",IF(COUNTIFS(Library!$A$2:$A$401,$A5,Library!$Z$2:$Z$401,">0")=0,"",_xlfn.MINIFS(Library!$Z$2:$Z$401,Library!$A$2:$A$401,$A5))) | K5: =IF($A5="","",IF(COUNTIFS(Library!$A$2:$A$401,$A5,Library!$Z$2:$Z$401,">0")=0,"",_xlfn.MAXIFS(Library!$Z$2:$Z$401,Library!$A$2:$A$401,$A5)))
A6: =IF(Products!$A$3="","",Products!$A$3) | B6: =IF($A6="","",Products!$C$3) | C6: =IF($A6="","",Products!$F$3) | D6: =IF($A6="","",COUNTIFS(Library!$A$2:$A$401,$A6)) | E6: =IF($A6="","",COUNTIFS(Library!$A$2:$A$401,$A6,Library!$L$2:$L$401,"Yes")) | F6: =IF($A6="","",COUNTIFS(Library!$A$2:$A$401,$A6,Library!$G$2:$G$401,"Clinical trial")+COUNTIFS(Library!$A$2:$A$401,$A6,Library!$G$2:$G$401,"Extension study")) | G6: =IF($A6="","",COUNTIFS(Library!$A$2:$A$401,$A6,Library!$G$2:$G$401,"Registry / Real-world study")+COUNTIFS(Library!$A$2:$A$401,$A6,Library!$G$2:$G$401,"Natural history study")) | H6: =IF($A6="","",COUNTIFS(Library!$A$2:$A$401,$A6,Library!$G$2:$G$401,"Guideline / Consensus")+COUNTIFS(Library!$A$2:$A$401,$A6,Library!$G$2:$G$401,"Expert recommendation")) | I6: =IF($A6="","",COUNTIFS(Library!$A$2:$A$401,$A6,Library!$AE$2:$AE$401,"Internal use only")+COUNTIFS(Library!$A$2:$A$401,$A6,Library!$AE$2:$AE$401,"Confidential")) | J6: =IF($A6="","",IF(COUNTIFS(Library!$A$2:$A$401,$A6,Library!$Z$2:$Z$401,">0")=0,"",_xlfn.MINIFS(Library!$Z$2:$Z$401,Library!$A$2:$A$401,$A6))) | K6: =IF($A6="","",IF(COUNTIFS(Library!$A$2:$A$401,$A6,Library!$Z$2:$Z$401,">0")=0,"",_xlfn.MAXIFS(Library!$Z$2:$Z$401,Library!$A$2:$A$401,$A6)))
A7: =IF(Products!$A$4="","",Products!$A$4) | B7: =IF($A7="","",Products!$C$4) | C7: =IF($A7="","",Products!$F$4) | D7: =IF($A7="","",COUNTIFS(Library!$A$2:$A$401,$A7)) | E7: =IF($A7="","",COUNTIFS(Library!$A$2:$A$401,$A7,Library!$L$2:$L$401,"Yes")) | F7: =IF($A7="","",COUNTIFS(Library!$A$2:$A$401,$A7,Library!$G$2:$G$401,"Clinical trial")+COUNTIFS(Library!$A$2:$A$401,$A7,Library!$G$2:$G$401,"Extension study")) | G7: =IF($A7="","",COUNTIFS(Library!$A$2:$A$401,$A7,Library!$G$2:$G$401,"Registry / Real-world study")+COUNTIFS(Library!$A$2:$A$401,$A7,Library!$G$2:$G$401,"Natural history study")) | H7: =IF($A7="","",COUNTIFS(Library!$A$2:$A$401,$A7,Library!$G$2:$G$401,"Guideline / Consensus")+COUNTIFS(Library!$A$2:$A$401,$A7,Library!$G$2:$G$401,"Expert recommendation")) | I7: =IF($A7="","",COUNTIFS(Library!$A$2:$A$401,$A7,Library!$AE$2:$AE$401,"Internal use only")+COUNTIFS(Library!$A$2:$A$401,$A7,Library!$AE$2:$AE$401,"Confidential")) | J7: =IF($A7="","",IF(COUNTIFS(Library!$A$2:$A$401,$A7,Library!$Z$2:$Z$401,">0")=0,"",_xlfn.MINIFS(Library!$Z$2:$Z$401,Library!$A$2:$A$401,$A7))) | K7: =IF($A7="","",IF(COUNTIFS(Library!$A$2:$A$401,$A7,Library!$Z$2:$Z$401,">0")=0,"",_xlfn.MAXIFS(Library!$Z$2:$Z$401,Library!$A$2:$A$401,$A7)))
A8: =IF(Products!$A$5="","",Products!$A$5) | B8: =IF($A8="","",Products!$C$5) | C8: =IF($A8="","",Products!$F$5) | D8: =IF($A8="","",COUNTIFS(Library!$A$2:$A$401,$A8)) | E8: =IF($A8="","",COUNTIFS(Library!$A$2:$A$401,$A8,Library!$L$2:$L$401,"Yes")) | F8: =IF($A8="","",COUNTIFS(Library!$A$2:$A$401,$A8,Library!$G$2:$G$401,"Clinical trial")+COUNTIFS(Library!$A$2:$A$401,$A8,Library!$G$2:$G$401,"Extension study")) | G8: =IF($A8="","",COUNTIFS(Library!$A$2:$A$401,$A8,Library!$G$2:$G$401,"Registry / Real-world study")+COUNTIFS(Library!$A$2:$A$401,$A8,Library!$G$2:$G$401,"Natural history study")) | H8: =IF($A8="","",COUNTIFS(Library!$A$2:$A$401,$A8,Library!$G$2:$G$401,"Guideline / Consensus")+COUNTIFS(Library!$A$2:$A$401,$A8,Library!$G$2:$G$401,"Expert recommendation")) | I8: =IF($A8="","",COUNTIFS(Library!$A$2:$A$401,$A8,Library!$AE$2:$AE$401,"Internal use only")+COUNTIFS(Library!$A$2:$A$401,$A8,Library!$AE$2:$AE$401,"Confidential")) | J8: =IF($A8="","",IF(COUNTIFS(Library!$A$2:$A$401,$A8,Library!$Z$2:$Z$401,">0")=0,"",_xlfn.MINIFS(Library!$Z$2:$Z$401,Library!$A$2:$A$401,$A8))) | K8: =IF($A8="","",IF(COUNTIFS(Library!$A$2:$A$401,$A8,Library!$Z$2:$Z$401,">0")=0,"",_xlfn.MAXIFS(Library!$Z$2:$Z$401,Library!$A$2:$A$401,$A8)))
A9: =IF(Products!$A$6="","",Products!$A$6) | B9: =IF($A9="","",Products!$C$6) | C9: =IF($A9="","",Products!$F$6) | D9: =IF($A9="","",COUNTIFS(Library!$A$2:$A$401,$A9)) | E9: =IF($A9="","",COUNTIFS(Library!$A$2:$A$401,$A9,Library!$L$2:$L$401,"Yes")) | F9: =IF($A9="","",COUNTIFS(Library!$A$2:$A$401,$A9,Library!$G$2:$G$401,"Clinical trial")+COUNTIFS(Library!$A$2:$A$401,$A9,Library!$G$2:$G$401,"Extension study")) | G9: =IF($A9="","",COUNTIFS(Library!$A$2:$A$401,$A9,Library!$G$2:$G$401,"Registry / Real-world study")+COUNTIFS(Library!$A$2:$A$401,$A9,Library!$G$2:$G$401,"Natural history study")) | H9: =IF($A9="","",COUNTIFS(Library!$A$2:$A$401,$A9,Library!$G$2:$G$401,"Guideline / Consensus")+COUNTIFS(Library!$A$2:$A$401,$A9,Library!$G$2:$G$401,"Expert recommendation")) | I9: =IF($A9="","",COUNTIFS(Library!$A$2:$A$401,$A9,Library!$AE$2:$AE$401,"Internal use only")+COUNTIFS(Library!$A$2:$A$401,$A9,Library!$AE$2:$AE$401,"Confidential")) | J9: =IF($A9="","",IF(COUNTIFS(Library!$A$2:$A$401,$A9,Library!$Z$2:$Z$401,">0")=0,"",_xlfn.MINIFS(Library!$Z$2:$Z$401,Library!$A$2:$A$401,$A9))) | K9: =IF($A9="","",IF(COUNTIFS(Library!$A$2:$A$401,$A9,Library!$Z$2:$Z$401,">0")=0,"",_xlfn.MAXIFS(Library!$Z$2:$Z$401,Library!$A$2:$A$401,$A9)))
A10: =IF(Products!$A$7="","",Products!$A$7) | B10: =IF($A10="","",Products!$C$7) | C10: =IF($A10="","",Products!$F$7) | D10: =IF($A10="","",COUNTIFS(Library!$A$2:$A$401,$A10)) | E10: =IF($A10="","",COUNTIFS(Library!$A$2:$A$401,$A10,Library!$L$2:$L$401,"Yes")) | F10: =IF($A10="","",COUNTIFS(Library!$A$2:$A$401,$A10,Library!$G$2:$G$401,"Clinical trial")+COUNTIFS(Library!$A$2:$A$401,$A10,Library!$G$2:$G$401,"Extension study")) | G10: =IF($A10="","",COUNTIFS(Library!$A$2:$A$401,$A10,Library!$G$2:$G$401,"Registry / Real-world study")+COUNTIFS(Library!$A$2:$A$401,$A10,Library!$G$2:$G$401,"Natural history study")) | H10: =IF($A10="","",COUNTIFS(Library!$A$2:$A$401,$A10,Library!$G$2:$G$401,"Guideline / Consensus")+COUNTIFS(Library!$A$2:$A$401,$A10,Library!$G$2:$G$401,"Expert recommendation")) | I10: =IF($A10="","",COUNTIFS(Library!$A$2:$A$401,$A10,Library!$AE$2:$AE$401,"Internal use only")+COUNTIFS(Library!$A$2:$A$401,$A10,Library!$AE$2:$AE$401,"Confidential")) | J10: =IF($A10="","",IF(COUNTIFS(Library!$A$2:$A$401,$A10,Library!$Z$2:$Z$401,">0")=0,"",_xlfn.MINIFS(Library!$Z$2:$Z$401,Library!$A$2:$A$401,$A10))) | K10: =IF($A10="","",IF(COUNTIFS(Library!$A$2:$A$401,$A10,Library!$Z$2:$Z$401,">0")=0,"",_xlfn.MAXIFS(Library!$Z$2:$Z$401,Library!$A$2:$A$401,$A10)))
A11: =IF(Products!$A$8="","",Products!$A$8) | B11: =IF($A11="","",Products!$C$8) | C11: =IF($A11="","",Products!$F$8) | D11: =IF($A11="","",COUNTIFS(Library!$A$2:$A$401,$A11)) | E11: =IF($A11="","",COUNTIFS(Library!$A$2:$A$401,$A11,Library!$L$2:$L$401,"Yes")) | F11: =IF($A11="","",COUNTIFS(Library!$A$2:$A$401,$A11,Library!$G$2:$G$401,"Clinical trial")+COUNTIFS(Library!$A$2:$A$401,$A11,Library!$G$2:$G$401,"Extension study")) | G11: =IF($A11="","",COUNTIFS(Library!$A$2:$A$401,$A11,Library!$G$2:$G$401,"Registry / Real-world study")+COUNTIFS(Library!$A$2:$A$401,$A11,Library!$G$2:$G$401,"Natural history study")) | H11: =IF($A11="","",COUNTIFS(Library!$A$2:$A$401,$A11,Library!$G$2:$G$401,"Guideline / Consensus")+COUNTIFS(Library!$A$2:$A$401,$A11,Library!$G$2:$G$401,"Expert recommendation")) | I11: =IF($A11="","",COUNTIFS(Library!$A$2:$A$401,$A11,Library!$AE$2:$AE$401,"Internal use only")+COUNTIFS(Library!$A$2:$A$401,$A11,Library!$AE$2:$AE$401,"Confidential")) | J11: =IF($A11="","",IF(COUNTIFS(Library!$A$2:$A$401,$A11,Library!$Z$2:$Z$401,">0")=0,"",_xlfn.MINIFS(Library!$Z$2:$Z$401,Library!$A$2:$A$401,$A11))) | K11: =IF($A11="","",IF(COUNTIFS(Library!$A$2:$A$401,$A11,Library!$Z$2:$Z$401,">0")=0,"",_xlfn.MAXIFS(Library!$Z$2:$Z$401,Library!$A$2:$A$401,$A11)))
A12: =IF(Products!$A$9="","",Products!$A$9) | B12: =IF($A12="","",Products!$C$9) | C12: =IF($A12="","",Products!$F$9) | D12: =IF($A12="","",COUNTIFS(Library!$A$2:$A$401,$A12)) | E12: =IF($A12="","",COUNTIFS(Library!$A$2:$A$401,$A12,Library!$L$2:$L$401,"Yes")) | F12: =IF($A12="","",COUNTIFS(Library!$A$2:$A$401,$A12,Library!$G$2:$G$401,"Clinical trial")+COUNTIFS(Library!$A$2:$A$401,$A12,Library!$G$2:$G$401,"Extension study")) | G12: =IF($A12="","",COUNTIFS(Library!$A$2:$A$401,$A12,Library!$G$2:$G$401,"Registry / Real-world study")+COUNTIFS(Library!$A$2:$A$401,$A12,Library!$G$2:$G$401,"Natural history study")) | H12: =IF($A12="","",COUNTIFS(Library!$A$2:$A$401,$A12,Library!$G$2:$G$401,"Guideline / Consensus")+COUNTIFS(Library!$A$2:$A$401,$A12,Library!$G$2:$G$401,"Expert recommendation")) | I12: =IF($A12="","",COUNTIFS(Library!$A$2:$A$401,$A12,Library!$AE$2:$AE$401,"Internal use only")+COUNTIFS(Library!$A$2:$A$401,$A12,Library!$AE$2:$AE$401,"Confidential")) | J12: =IF($A12="","",IF(COUNTIFS(Library!$A$2:$A$401,$A12,Library!$Z$2:$Z$401,">0")=0,"",_xlfn.MINIFS(Library!$Z$2:$Z$401,Library!$A$2:$A$401,$A12))) | K12: =IF($A12="","",IF(COUNTIFS(Library!$A$2:$A$401,$A12,Library!$Z$2:$Z$401,">0")=0,"",_xlfn.MAXIFS(Library!$Z$2:$Z$401,Library!$A$2:$A$401,$A12)))
A13: =IF(Products!$A$10="","",Products!$A$10) | B13: =IF($A13="","",Products!$C$10) | C13: =IF($A13="","",Products!$F$10) | D13: =IF($A13="","",COUNTIFS(Library!$A$2:$A$401,$A13)) | E13: =IF($A13="","",COUNTIFS(Library!$A$2:$A$401,$A13,Library!$L$2:$L$401,"Yes")) | F13: =IF($A13="","",COUNTIFS(Library!$A$2:$A$401,$A13,Library!$G$2:$G$401,"Clinical trial")+COUNTIFS(Library!$A$2:$A$401,$A13,Library!$G$2:$G$401,"Extension study")) | G13: =IF($A13="","",COUNTIFS(Library!$A$2:$A$401,$A13,Library!$G$2:$G$401,"Registry / Real-world study")+COUNTIFS(Library!$A$2:$A$401,$A13,Library!$G$2:$G$401,"Natural history study")) | H13: =IF($A13="","",COUNTIFS(Library!$A$2:$A$401,$A13,Library!$G$2:$G$401,"Guideline / Consensus")+COUNTIFS(Library!$A$2:$A$401,$A13,Library!$G$2:$G$401,"Expert recommendation")) | I13: =IF($A13="","",COUNTIFS(Library!$A$2:$A$401,$A13,Library!$AE$2:$AE$401,"Internal use only")+COUNTIFS(Library!$A$2:$A$401,$A13,Library!$AE$2:$AE$401,"Confidential")) | J13: =IF($A13="","",IF(COUNTIFS(Library!$A$2:$A$401,$A13,Library!$Z$2:$Z$401,">0")=0,"",_xlfn.MINIFS(Library!$Z$2:$Z$401,Library!$A$2:$A$401,$A13))) | K13: =IF($A13="","",IF(COUNTIFS(Library!$A$2:$A$401,$A13,Library!$Z$2:$Z$401,">0")=0,"",_xlfn.MAXIFS(Library!$Z$2:$Z$401,Library!$A$2:$A$401,$A13)))
A14: =IF(Products!$A$11="","",Products!$A$11) | B14: =IF($A14="","",Products!$C$11) | C14: =IF($A14="","",Products!$F$11) | D14: =IF($A14="","",COUNTIFS(Library!$A$2:$A$401,$A14)) | E14: =IF($A14="","",COUNTIFS(Library!$A$2:$A$401,$A14,Library!$L$2:$L$401,"Yes")) | F14: =IF($A14="","",COUNTIFS(Library!$A$2:$A$401,$A14,Library!$G$2:$G$401,"Clinical trial")+COUNTIFS(Library!$A$2:$A$401,$A14,Library!$G$2:$G$401,"Extension study")) | G14: =IF($A14="","",COUNTIFS(Library!$A$2:$A$401,$A14,Library!$G$2:$G$401,"Registry / Real-world study")+COUNTIFS(Library!$A$2:$A$401,$A14,Library!$G$2:$G$401,"Natural history study")) | H14: =IF($A14="","",COUNTIFS(Library!$A$2:$A$401,$A14,Library!$G$2:$G$401,"Guideline / Consensus")+COUNTIFS(Library!$A$2:$A$401,$A14,Library!$G$2:$G$401,"Expert recommendation")) | I14: =IF($A14="","",COUNTIFS(Library!$A$2:$A$401,$A14,Library!$AE$2:$AE$401,"Internal use only")+COUNTIFS(Library!$A$2:$A$401,$A14,Library!$AE$2:$AE$401,"Confidential")) | J14: =IF($A14="","",IF(COUNTIFS(Library!$A$2:$A$401,$A14,Library!$Z$2:$Z$401,">0")=0,"",_xlfn.MINIFS(Library!$Z$2:$Z$401,Library!$A$2:$A$401,$A14))) | K14: =IF($A14="","",IF(COUNTIFS(Library!$A$2:$A$401,$A14,Library!$Z$2:$Z$401,">0")=0,"",_xlfn.MAXIFS(Library!$Z$2:$Z$401,Library!$A$2:$A$401,$A14)))
A15: =IF(Products!$A$12="","",Products!$A$12) | B15: =IF($A15="","",Products!$C$12) | C15: =IF($A15="","",Products!$F$12) | D15: =IF($A15="","",COUNTIFS(Library!$A$2:$A$401,$A15)) | E15: =IF($A15="","",COUNTIFS(Library!$A$2:$A$401,$A15,Library!$L$2:$L$401,"Yes")) | F15: =IF($A15="","",COUNTIFS(Library!$A$2:$A$401,$A15,Library!$G$2:$G$401,"Clinical trial")+COUNTIFS(Library!$A$2:$A$401,$A15,Library!$G$2:$G$401,"Extension study")) | G15: =IF($A15="","",COUNTIFS(Library!$A$2:$A$401,$A15,Library!$G$2:$G$401,"Registry / Real-world study")+COUNTIFS(Library!$A$2:$A$401,$A15,Library!$G$2:$G$401,"Natural history study")) | H15: =IF($A15="","",COUNTIFS(Library!$A$2:$A$401,$A15,Library!$G$2:$G$401,"Guideline / Consensus")+COUNTIFS(Library!$A$2:$A$401,$A15,Library!$G$2:$G$401,"Expert recommendation")) | I15: =IF($A15="","",COUNTIFS(Library!$A$2:$A$401,$A15,Library!$AE$2:$AE$401,"Internal use only")+COUNTIFS(Library!$A$2:$A$401,$A15,Library!$AE$2:$AE$401,"Confidential")) | J15: =IF($A15="","",IF(COUNTIFS(Library!$A$2:$A$401,$A15,Library!$Z$2:$Z$401,">0")=0,"",_xlfn.MINIFS(Library!$Z$2:$Z$401,Library!$A$2:$A$401,$A15))) | K15: =IF($A15="","",IF(COUNTIFS(Library!$A$2:$A$401,$A15,Library!$Z$2:$Z$401,">0")=0,"",_xlfn.MAXIFS(Library!$Z$2:$Z$401,Library!$A$2:$A$401,$A15)))
A16: =IF(Products!$A$13="","",Products!$A$13) | B16: =IF($A16="","",Products!$C$13) | C16: =IF($A16="","",Products!$F$13) | D16: =IF($A16="","",COUNTIFS(Library!$A$2:$A$401,$A16)) | E16: =IF($A16="","",COUNTIFS(Library!$A$2:$A$401,$A16,Library!$L$2:$L$401,"Yes")) | F16: =IF($A16="","",COUNTIFS(Library!$A$2:$A$401,$A16,Library!$G$2:$G$401,"Clinical trial")+COUNTIFS(Library!$A$2:$A$401,$A16,Library!$G$2:$G$401,"Extension study")) | G16: =IF($A16="","",COUNTIFS(Library!$A$2:$A$401,$A16,Library!$G$2:$G$401,"Registry / Real-world study")+COUNTIFS(Library!$A$2:$A$401,$A16,Library!$G$2:$G$401,"Natural history study")) | H16: =IF($A16="","",COUNTIFS(Library!$A$2:$A$401,$A16,Library!$G$2:$G$401,"Guideline / Consensus")+COUNTIFS(Library!$A$2:$A$401,$A16,Library!$G$2:$G$401,"Expert recommendation")) | I16: =IF($A16="","",COUNTIFS(Library!$A$2:$A$401,$A16,Library!$AE$2:$AE$401,"Internal use only")+COUNTIFS(Library!$A$2:$A$401,$A16,Library!$AE$2:$AE$401,"Confidential")) | J16: =IF($A16="","",IF(COUNTIFS(Library!$A$2:$A$401,$A16,Library!$Z$2:$Z$401,">0")=0,"",_xlfn.MINIFS(Library!$Z$2:$Z$401,Library!$A$2:$A$401,$A16))) | K16: =IF($A16="","",IF(COUNTIFS(Library!$A$2:$A$401,$A16,Library!$Z$2:$Z$401,">0")=0,"",_xlfn.MAXIFS(Library!$Z$2:$Z$401,Library!$A$2:$A$401,$A16)))
A17: =IF(Products!$A$14="","",Products!$A$14) | B17: =IF($A17="","",Products!$C$14) | C17: =IF($A17="","",Products!$F$14) | D17: =IF($A17="","",COUNTIFS(Library!$A$2:$A$401,$A17)) | E17: =IF($A17="","",COUNTIFS(Library!$A$2:$A$401,$A17,Library!$L$2:$L$401,"Yes")) | F17: =IF($A17="","",COUNTIFS(Library!$A$2:$A$401,$A17,Library!$G$2:$G$401,"Clinical trial")+COUNTIFS(Library!$A$2:$A$401,$A17,Library!$G$2:$G$401,"Extension study")) | G17: =IF($A17="","",COUNTIFS(Library!$A$2:$A$401,$A17,Library!$G$2:$G$401,"Registry / Real-world study")+COUNTIFS(Library!$A$2:$A$401,$A17,Library!$G$2:$G$401,"Natural history study")) | H17: =IF($A17="","",COUNTIFS(Library!$A$2:$A$401,$A17,Library!$G$2:$G$401,"Guideline / Consensus")+COUNTIFS(Library!$A$2:$A$401,$A17,Library!$G$2:$G$401,"Expert recommendation")) | I17: =IF($A17="","",COUNTIFS(Library!$A$2:$A$401,$A17,Library!$AE$2:$AE$401,"Internal use only")+COUNTIFS(Library!$A$2:$A$401,$A17,Library!$AE$2:$AE$401,"Confidential")) | J17: =IF($A17="","",IF(COUNTIFS(Library!$A$2:$A$401,$A17,Library!$Z$2:$Z$401,">0")=0,"",_xlfn.MINIFS(Library!$Z$2:$Z$401,Library!$A$2:$A$401,$A17))) | K17: =IF($A17="","",IF(COUNTIFS(Library!$A$2:$A$401,$A17,Library!$Z$2:$Z$401,">0")=0,"",_xlfn.MAXIFS(Library!$Z$2:$Z$401,Library!$A$2:$A$401,$A17)))
A18: =IF(Products!$A$15="","",Products!$A$15) | B18: =IF($A18="","",Products!$C$15) | C18: =IF($A18="","",Products!$F$15) | D18: =IF($A18="","",COUNTIFS(Library!$A$2:$A$401,$A18)) | E18: =IF($A18="","",COUNTIFS(Library!$A$2:$A$401,$A18,Library!$L$2:$L$401,"Yes")) | F18: =IF($A18="","",COUNTIFS(Library!$A$2:$A$401,$A18,Library!$G$2:$G$401,"Clinical trial")+COUNTIFS(Library!$A$2:$A$401,$A18,Library!$G$2:$G$401,"Extension study")) | G18: =IF($A18="","",COUNTIFS(Library!$A$2:$A$401,$A18,Library!$G$2:$G$401,"Registry / Real-world study")+COUNTIFS(Library!$A$2:$A$401,$A18,Library!$G$2:$G$401,"Natural history study")) | H18: =IF($A18="","",COUNTIFS(Library!$A$2:$A$401,$A18,Library!$G$2:$G$401,"Guideline / Consensus")+COUNTIFS(Library!$A$2:$A$401,$A18,Library!$G$2:$G$401,"Expert recommendation")) | I18: =IF($A18="","",COUNTIFS(Library!$A$2:$A$401,$A18,Library!$AE$2:$AE$401,"Internal use only")+COUNTIFS(Library!$A$2:$A$401,$A18,Library!$AE$2:$AE$401,"Confidential")) | J18: =IF($A18="","",IF(COUNTIFS(Library!$A$2:$A$401,$A18,Library!$Z$2:$Z$401,">0")=0,"",_xlfn.MINIFS(Library!$Z$2:$Z$401,Library!$A$2:$A$401,$A18))) | K18: =IF($A18="","",IF(COUNTIFS(Library!$A$2:$A$401,$A18,Library!$Z$2:$Z$401,">0")=0,"",_xlfn.MAXIFS(Library!$Z$2:$Z$401,Library!$A$2:$A$401,$A18)))
A19: =IF(Products!$A$16="","",Products!$A$16) | B19: =IF($A19="","",Products!$C$16) | C19: =IF($A19="","",Products!$F$16) | D19: =IF($A19="","",COUNTIFS(Library!$A$2:$A$401,$A19)) | E19: =IF($A19="","",COUNTIFS(Library!$A$2:$A$401,$A19,Library!$L$2:$L$401,"Yes")) | F19: =IF($A19="","",COUNTIFS(Library!$A$2:$A$401,$A19,Library!$G$2:$G$401,"Clinical trial")+COUNTIFS(Library!$A$2:$A$401,$A19,Library!$G$2:$G$401,"Extension study")) | G19: =IF($A19="","",COUNTIFS(Library!$A$2:$A$401,$A19,Library!$G$2:$G$401,"Registry / Real-world study")+COUNTIFS(Library!$A$2:$A$401,$A19,Library!$G$2:$G$401,"Natural history study")) | H19: =IF($A19="","",COUNTIFS(Library!$A$2:$A$401,$A19,Library!$G$2:$G$401,"Guideline / Consensus")+COUNTIFS(Library!$A$2:$A$401,$A19,Library!$G$2:$G$401,"Expert recommendation")) | I19: =IF($A19="","",COUNTIFS(Library!$A$2:$A$401,$A19,Library!$AE$2:$AE$401,"Internal use only")+COUNTIFS(Library!$A$2:$A$401,$A19,Library!$AE$2:$AE$401,"Confidential")) | J19: =IF($A19="","",IF(COUNTIFS(Library!$A$2:$A$401,$A19,Library!$Z$2:$Z$401,">0")=0,"",_xlfn.MINIFS(Library!$Z$2:$Z$401,Library!$A$2:$A$401,$A19))) | K19: =IF($A19="","",IF(COUNTIFS(Library!$A$2:$A$401,$A19,Library!$Z$2:$Z$401,">0")=0,"",_xlfn.MAXIFS(Library!$Z$2:$Z$401,Library!$A$2:$A$401,$A19)))
A20: =IF(Products!$A$17="","",Products!$A$17) | B20: =IF($A20="","",Products!$C$17) | C20: =IF($A20="","",Products!$F$17) | D20: =IF($A20="","",COUNTIFS(Library!$A$2:$A$401,$A20)) | E20: =IF($A20="","",COUNTIFS(Library!$A$2:$A$401,$A20,Library!$L$2:$L$401,"Yes")) | F20: =IF($A20="","",COUNTIFS(Library!$A$2:$A$401,$A20,Library!$G$2:$G$401,"Clinical trial")+COUNTIFS(Library!$A$2:$A$401,$A20,Library!$G$2:$G$401,"Extension study")) | G20: =IF($A20="","",COUNTIFS(Library!$A$2:$A$401,$A20,Library!$G$2:$G$401,"Registry / Real-world study")+COUNTIFS(Library!$A$2:$A$401,$A20,Library!$G$2:$G$401,"Natural history study")) | H20: =IF($A20="","",COUNTIFS(Library!$A$2:$A$401,$A20,Library!$G$2:$G$401,"Guideline / Consensus")+COUNTIFS(Library!$A$2:$A$401,$A20,Library!$G$2:$G$401,"Expert recommendation")) | I20: =IF($A20="","",COUNTIFS(Library!$A$2:$A$401,$A20,Library!$AE$2:$AE$401,"Internal use only")+COUNTIFS(Library!$A$2:$A$401,$A20,Library!$AE$2:$AE$401,"Confidential")) | J20: =IF($A20="","",IF(COUNTIFS(Library!$A$2:$A$401,$A20,Library!$Z$2:$Z$401,">0")=0,"",_xlfn.MINIFS(Library!$Z$2:$Z$401,Library!$A$2:$A$401,$A20))) | K20: =IF($A20="","",IF(COUNTIFS(Library!$A$2:$A$401,$A20,Library!$Z$2:$Z$401,">0")=0,"",_xlfn.MAXIFS(Library!$Z$2:$Z$401,Library!$A$2:$A$401,$A20)))
A21: =IF(Products!$A$18="","",Products!$A$18) | B21: =IF($A21="","",Products!$C$18) | C21: =IF($A21="","",Products!$F$18) | D21: =IF($A21="","",COUNTIFS(Library!$A$2:$A$401,$A21)) | E21: =IF($A21="","",COUNTIFS(Library!$A$2:$A$401,$A21,Library!$L$2:$L$401,"Yes")) | F21: =IF($A21="","",COUNTIFS(Library!$A$2:$A$401,$A21,Library!$G$2:$G$401,"Clinical trial")+COUNTIFS(Library!$A$2:$A$401,$A21,Library!$G$2:$G$401,"Extension study")) | G21: =IF($A21="","",COUNTIFS(Library!$A$2:$A$401,$A21,Library!$G$2:$G$401,"Registry / Real-world study")+COUNTIFS(Library!$A$2:$A$401,$A21,Library!$G$2:$G$401,"Natural history study")) | H21: =IF($A21="","",COUNTIFS(Library!$A$2:$A$401,$A21,Library!$G$2:$G$401,"Guideline / Consensus")+COUNTIFS(Library!$A$2:$A$401,$A21,Library!$G$2:$G$401,"Expert recommendation")) | I21: =IF($A21="","",COUNTIFS(Library!$A$2:$A$401,$A21,Library!$AE$2:$AE$401,"Internal use only")+COUNTIFS(Library!$A$2:$A$401,$A21,Library!$AE$2:$AE$401,"Confidential")) | J21: =IF($A21="","",IF(COUNTIFS(Library!$A$2:$A$401,$A21,Library!$Z$2:$Z$401,">0")=0,"",_xlfn.MINIFS(Library!$Z$2:$Z$401,Library!$A$2:$A$401,$A21))) | K21: =IF($A21="","",IF(COUNTIFS(Library!$A$2:$A$401,$A21,Library!$Z$2:$Z$401,">0")=0,"",_xlfn.MAXIFS(Library!$Z$2:$Z$401,Library!$A$2:$A$401,$A21)))
A22: =IF(Products!$A$19="","",Products!$A$19) | B22: =IF($A22="","",Products!$C$19) | C22: =IF($A22="","",Products!$F$19) | D22: =IF($A22="","",COUNTIFS(Library!$A$2:$A$401,$A22)) | E22: =IF($A22="","",COUNTIFS(Library!$A$2:$A$401,$A22,Library!$L$2:$L$401,"Yes")) | F22: =IF($A22="","",COUNTIFS(Library!$A$2:$A$401,$A22,Library!$G$2:$G$401,"Clinical trial")+COUNTIFS(Library!$A$2:$A$401,$A22,Library!$G$2:$G$401,"Extension study")) | G22: =IF($A22="","",COUNTIFS(Library!$A$2:$A$401,$A22,Library!$G$2:$G$401,"Registry / Real-world study")+COUNTIFS(Library!$A$2:$A$401,$A22,Library!$G$2:$G$401,"Natural history study")) | H22: =IF($A22="","",COUNTIFS(Library!$A$2:$A$401,$A22,Library!$G$2:$G$401,"Guideline / Consensus")+COUNTIFS(Library!$A$2:$A$401,$A22,Library!$G$2:$G$401,"Expert recommendation")) | I22: =IF($A22="","",COUNTIFS(Library!$A$2:$A$401,$A22,Library!$AE$2:$AE$401,"Internal use only")+COUNTIFS(Library!$A$2:$A$401,$A22,Library!$AE$2:$AE$401,"Confidential")) | J22: =IF($A22="","",IF(COUNTIFS(Library!$A$2:$A$401,$A22,Library!$Z$2:$Z$401,">0")=0,"",_xlfn.MINIFS(Library!$Z$2:$Z$401,Library!$A$2:$A$401,$A22))) | K22: =IF($A22="","",IF(COUNTIFS(Library!$A$2:$A$401,$A22,Library!$Z$2:$Z$401,">0")=0,"",_xlfn.MAXIFS(Library!$Z$2:$Z$401,Library!$A$2:$A$401,$A22)))
A23: =IF(Products!$A$20="","",Products!$A$20) | B23: =IF($A23="","",Products!$C$20) | C23: =IF($A23="","",Products!$F$20) | D23: =IF($A23="","",COUNTIFS(Library!$A$2:$A$401,$A23)) | E23: =IF($A23="","",COUNTIFS(Library!$A$2:$A$401,$A23,Library!$L$2:$L$401,"Yes")) | F23: =IF($A23="","",COUNTIFS(Library!$A$2:$A$401,$A23,Library!$G$2:$G$401,"Clinical trial")+COUNTIFS(Library!$A$2:$A$401,$A23,Library!$G$2:$G$401,"Extension study")) | G23: =IF($A23="","",COUNTIFS(Library!$A$2:$A$401,$A23,Library!$G$2:$G$401,"Registry / Real-world study")+COUNTIFS(Library!$A$2:$A$401,$A23,Library!$G$2:$G$401,"Natural history study")) | H23: =IF($A23="","",COUNTIFS(Library!$A$2:$A$401,$A23,Library!$G$2:$G$401,"Guideline / Consensus")+COUNTIFS(Library!$A$2:$A$401,$A23,Library!$G$2:$G$401,"Expert recommendation")) | I23: =IF($A23="","",COUNTIFS(Library!$A$2:$A$401,$A23,Library!$AE$2:$AE$401,"Internal use only")+COUNTIFS(Library!$A$2:$A$401,$A23,Library!$AE$2:$AE$401,"Confidential")) | J23: =IF($A23="","",IF(COUNTIFS(Library!$A$2:$A$401,$A23,Library!$Z$2:$Z$401,">0")=0,"",_xlfn.MINIFS(Library!$Z$2:$Z$401,Library!$A$2:$A$401,$A23))) | K23: =IF($A23="","",IF(COUNTIFS(Library!$A$2:$A$401,$A23,Library!$Z$2:$Z$401,">0")=0,"",_xlfn.MAXIFS(Library!$Z$2:$Z$401,Library!$A$2:$A$401,$A23)))
A24: =IF(Products!$A$21="","",Products!$A$21) | B24: =IF($A24="","",Products!$C$21) | C24: =IF($A24="","",Products!$F$21) | D24: =IF($A24="","",COUNTIFS(Library!$A$2:$A$401,$A24)) | E24: =IF($A24="","",COUNTIFS(Library!$A$2:$A$401,$A24,Library!$L$2:$L$401,"Yes")) | F24: =IF($A24="","",COUNTIFS(Library!$A$2:$A$401,$A24,Library!$G$2:$G$401,"Clinical trial")+COUNTIFS(Library!$A$2:$A$401,$A24,Library!$G$2:$G$401,"Extension study")) | G24: =IF($A24="","",COUNTIFS(Library!$A$2:$A$401,$A24,Library!$G$2:$G$401,"Registry / Real-world study")+COUNTIFS(Library!$A$2:$A$401,$A24,Library!$G$2:$G$401,"Natural history study")) | H24: =IF($A24="","",COUNTIFS(Library!$A$2:$A$401,$A24,Library!$G$2:$G$401,"Guideline / Consensus")+COUNTIFS(Library!$A$2:$A$401,$A24,Library!$G$2:$G$401,"Expert recommendation")) | I24: =IF($A24="","",COUNTIFS(Library!$A$2:$A$401,$A24,Library!$AE$2:$AE$401,"Internal use only")+COUNTIFS(Library!$A$2:$A$401,$A24,Library!$AE$2:$AE$401,"Confidential")) | J24: =IF($A24="","",IF(COUNTIFS(Library!$A$2:$A$401,$A24,Library!$Z$2:$Z$401,">0")=0,"",_xlfn.MINIFS(Library!$Z$2:$Z$401,Library!$A$2:$A$401,$A24))) | K24: =IF($A24="","",IF(COUNTIFS(Library!$A$2:$A$401,$A24,Library!$Z$2:$Z$401,">0")=0,"",_xlfn.MAXIFS(Library!$Z$2:$Z$401,Library!$A$2:$A$401,$A24)))
A25: =IF(Products!$A$22="","",Products!$A$22) | B25: =IF($A25="","",Products!$C$22) | C25: =IF($A25="","",Products!$F$22) | D25: =IF($A25="","",COUNTIFS(Library!$A$2:$A$401,$A25)) | E25: =IF($A25="","",COUNTIFS(Library!$A$2:$A$401,$A25,Library!$L$2:$L$401,"Yes")) | F25: =IF($A25="","",COUNTIFS(Library!$A$2:$A$401,$A25,Library!$G$2:$G$401,"Clinical trial")+COUNTIFS(Library!$A$2:$A$401,$A25,Library!$G$2:$G$401,"Extension study")) | G25: =IF($A25="","",COUNTIFS(Library!$A$2:$A$401,$A25,Library!$G$2:$G$401,"Registry / Real-world study")+COUNTIFS(Library!$A$2:$A$401,$A25,Library!$G$2:$G$401,"Natural history study")) | H25: =IF($A25="","",COUNTIFS(Library!$A$2:$A$401,$A25,Library!$G$2:$G$401,"Guideline / Consensus")+COUNTIFS(Library!$A$2:$A$401,$A25,Library!$G$2:$G$401,"Expert recommendation")) | I25: =IF($A25="","",COUNTIFS(Library!$A$2:$A$401,$A25,Library!$AE$2:$AE$401,"Internal use only")+COUNTIFS(Library!$A$2:$A$401,$A25,Library!$AE$2:$AE$401,"Confidential")) | J25: =IF($A25="","",IF(COUNTIFS(Library!$A$2:$A$401,$A25,Library!$Z$2:$Z$401,">0")=0,"",_xlfn.MINIFS(Library!$Z$2:$Z$401,Library!$A$2:$A$401,$A25))) | K25: =IF($A25="","",IF(COUNTIFS(Library!$A$2:$A$401,$A25,Library!$Z$2:$Z$401,">0")=0,"",_xlfn.MAXIFS(Library!$Z$2:$Z$401,Library!$A$2:$A$401,$A25)))
A26: =IF(Products!$A$23="","",Products!$A$23) | B26: =IF($A26="","",Products!$C$23) | C26: =IF($A26="","",Products!$F$23) | D26: =IF($A26="","",COUNTIFS(Library!$A$2:$A$401,$A26)) | E26: =IF($A26="","",COUNTIFS(Library!$A$2:$A$401,$A26,Library!$L$2:$L$401,"Yes")) | F26: =IF($A26="","",COUNTIFS(Library!$A$2:$A$401,$A26,Library!$G$2:$G$401,"Clinical trial")+COUNTIFS(Library!$A$2:$A$401,$A26,Library!$G$2:$G$401,"Extension study")) | G26: =IF($A26="","",COUNTIFS(Library!$A$2:$A$401,$A26,Library!$G$2:$G$401,"Registry / Real-world study")+COUNTIFS(Library!$A$2:$A$401,$A26,Library!$G$2:$G$401,"Natural history study")) | H26: =IF($A26="","",COUNTIFS(Library!$A$2:$A$401,$A26,Library!$G$2:$G$401,"Guideline / Consensus")+COUNTIFS(Library!$A$2:$A$401,$A26,Library!$G$2:$G$401,"Expert recommendation")) | I26: =IF($A26="","",COUNTIFS(Library!$A$2:$A$401,$A26,Library!$AE$2:$AE$401,"Internal use only")+COUNTIFS(Library!$A$2:$A$401,$A26,Library!$AE$2:$AE$401,"Confidential")) | J26: =IF($A26="","",IF(COUNTIFS(Library!$A$2:$A$401,$A26,Library!$Z$2:$Z$401,">0")=0,"",_xlfn.MINIFS(Library!$Z$2:$Z$401,Library!$A$2:$A$401,$A26))) | K26: =IF($A26="","",IF(COUNTIFS(Library!$A$2:$A$401,$A26,Library!$Z$2:$Z$401,">0")=0,"",_xlfn.MAXIFS(Library!$Z$2:$Z$401,Library!$A$2:$A$401,$A26)))
A27: =IF(Products!$A$24="","",Products!$A$24) | B27: =IF($A27="","",Products!$C$24) | C27: =IF($A27="","",Products!$F$24) | D27: =IF($A27="","",COUNTIFS(Library!$A$2:$A$401,$A27)) | E27: =IF($A27="","",COUNTIFS(Library!$A$2:$A$401,$A27,Library!$L$2:$L$401,"Yes")) | F27: =IF($A27="","",COUNTIFS(Library!$A$2:$A$401,$A27,Library!$G$2:$G$401,"Clinical trial")+COUNTIFS(Library!$A$2:$A$401,$A27,Library!$G$2:$G$401,"Extension study")) | G27: =IF($A27="","",COUNTIFS(Library!$A$2:$A$401,$A27,Library!$G$2:$G$401,"Registry / Real-world study")+COUNTIFS(Library!$A$2:$A$401,$A27,Library!$G$2:$G$401,"Natural history study")) | H27: =IF($A27="","",COUNTIFS(Library!$A$2:$A$401,$A27,Library!$G$2:$G$401,"Guideline / Consensus")+COUNTIFS(Library!$A$2:$A$401,$A27,Library!$G$2:$G$401,"Expert recommendation")) | I27: =IF($A27="","",COUNTIFS(Library!$A$2:$A$401,$A27,Library!$AE$2:$AE$401,"Internal use only")+COUNTIFS(Library!$A$2:$A$401,$A27,Library!$AE$2:$AE$401,"Confidential")) | J27: =IF($A27="","",IF(COUNTIFS(Library!$A$2:$A$401,$A27,Library!$Z$2:$Z$401,">0")=0,"",_xlfn.MINIFS(Library!$Z$2:$Z$401,Library!$A$2:$A$401,$A27))) | K27: =IF($A27="","",IF(COUNTIFS(Library!$A$2:$A$401,$A27,Library!$Z$2:$Z$401,">0")=0,"",_xlfn.MAXIFS(Library!$Z$2:$Z$401,Library!$A$2:$A$401,$A27)))
A28: =IF(Products!$A$25="","",Products!$A$25) | B28: =IF($A28="","",Products!$C$25) | C28: =IF($A28="","",Products!$F$25) | D28: =IF($A28="","",COUNTIFS(Library!$A$2:$A$401,$A28)) | E28: =IF($A28="","",COUNTIFS(Library!$A$2:$A$401,$A28,Library!$L$2:$L$401,"Yes")) | F28: =IF($A28="","",COUNTIFS(Library!$A$2:$A$401,$A28,Library!$G$2:$G$401,"Clinical trial")+COUNTIFS(Library!$A$2:$A$401,$A28,Library!$G$2:$G$401,"Extension study")) | G28: =IF($A28="","",COUNTIFS(Library!$A$2:$A$401,$A28,Library!$G$2:$G$401,"Registry / Real-world study")+COUNTIFS(Library!$A$2:$A$401,$A28,Library!$G$2:$G$401,"Natural history study")) | H28: =IF($A28="","",COUNTIFS(Library!$A$2:$A$401,$A28,Library!$G$2:$G$401,"Guideline / Consensus")+COUNTIFS(Library!$A$2:$A$401,$A28,Library!$G$2:$G$401,"Expert recommendation")) | I28: =IF($A28="","",COUNTIFS(Library!$A$2:$A$401,$A28,Library!$AE$2:$AE$401,"Internal use only")+COUNTIFS(Library!$A$2:$A$401,$A28,Library!$AE$2:$AE$401,"Confidential")) | J28: =IF($A28="","",IF(COUNTIFS(Library!$A$2:$A$401,$A28,Library!$Z$2:$Z$401,">0")=0,"",_xlfn.MINIFS(Library!$Z$2:$Z$401,Library!$A$2:$A$401,$A28))) | K28: =IF($A28="","",IF(COUNTIFS(Library!$A$2:$A$401,$A28,Library!$Z$2:$Z$401,">0")=0,"",_xlfn.MAXIFS(Library!$Z$2:$Z$401,Library!$A$2:$A$401,$A28)))
A29: =IF(Products!$A$26="","",Products!$A$26) | B29: =IF($A29="","",Products!$C$26) | C29: =IF($A29="","",Products!$F$26) | D29: =IF($A29="","",COUNTIFS(Library!$A$2:$A$401,$A29)) | E29: =IF($A29="","",COUNTIFS(Library!$A$2:$A$401,$A29,Library!$L$2:$L$401,"Yes")) | F29: =IF($A29="","",COUNTIFS(Library!$A$2:$A$401,$A29,Library!$G$2:$G$401,"Clinical trial")+COUNTIFS(Library!$A$2:$A$401,$A29,Library!$G$2:$G$401,"Extension study")) | G29: =IF($A29="","",COUNTIFS(Library!$A$2:$A$401,$A29,Library!$G$2:$G$401,"Registry / Real-world study")+COUNTIFS(Library!$A$2:$A$401,$A29,Library!$G$2:$G$401,"Natural history study")) | H29: =IF($A29="","",COUNTIFS(Library!$A$2:$A$401,$A29,Library!$G$2:$G$401,"Guideline / Consensus")+COUNTIFS(Library!$A$2:$A$401,$A29,Library!$G$2:$G$401,"Expert recommendation")) | I29: =IF($A29="","",COUNTIFS(Library!$A$2:$A$401,$A29,Library!$AE$2:$AE$401,"Internal use only")+COUNTIFS(Library!$A$2:$A$401,$A29,Library!$AE$2:$AE$401,"Confidential")) | J29: =IF($A29="","",IF(COUNTIFS(Library!$A$2:$A$401,$A29,Library!$Z$2:$Z$401,">0")=0,"",_xlfn.MINIFS(Library!$Z$2:$Z$401,Library!$A$2:$A$401,$A29))) | K29: =IF($A29="","",IF(COUNTIFS(Library!$A$2:$A$401,$A29,Library!$Z$2:$Z$401,">0")=0,"",_xlfn.MAXIFS(Library!$Z$2:$Z$401,Library!$A$2:$A$401,$A29)))
A30: =IF(Products!$A$27="","",Products!$A$27) | B30: =IF($A30="","",Products!$C$27) | C30: =IF($A30="","",Products!$F$27) | D30: =IF($A30="","",COUNTIFS(Library!$A$2:$A$401,$A30)) | E30: =IF($A30="","",COUNTIFS(Library!$A$2:$A$401,$A30,Library!$L$2:$L$401,"Yes")) | F30: =IF($A30="","",COUNTIFS(Library!$A$2:$A$401,$A30,Library!$G$2:$G$401,"Clinical trial")+COUNTIFS(Library!$A$2:$A$401,$A30,Library!$G$2:$G$401,"Extension study")) | G30: =IF($A30="","",COUNTIFS(Library!$A$2:$A$401,$A30,Library!$G$2:$G$401,"Registry / Real-world study")+COUNTIFS(Library!$A$2:$A$401,$A30,Library!$G$2:$G$401,"Natural history study")) | H30: =IF($A30="","",COUNTIFS(Library!$A$2:$A$401,$A30,Library!$G$2:$G$401,"Guideline / Consensus")+COUNTIFS(Library!$A$2:$A$401,$A30,Library!$G$2:$G$401,"Expert recommendation")) | I30: =IF($A30="","",COUNTIFS(Library!$A$2:$A$401,$A30,Library!$AE$2:$AE$401,"Internal use only")+COUNTIFS(Library!$A$2:$A$401,$A30,Library!$AE$2:$AE$401,"Confidential")) | J30: =IF($A30="","",IF(COUNTIFS(Library!$A$2:$A$401,$A30,Library!$Z$2:$Z$401,">0")=0,"",_xlfn.MINIFS(Library!$Z$2:$Z$401,Library!$A$2:$A$401,$A30))) | K30: =IF($A30="","",IF(COUNTIFS(Library!$A$2:$A$401,$A30,Library!$Z$2:$Z$401,">0")=0,"",_xlfn.MAXIFS(Library!$Z$2:$Z$401,Library!$A$2:$A$401,$A30)))
A31: =IF(Products!$A$28="","",Products!$A$28) | B31: =IF($A31="","",Products!$C$28) | C31: =IF($A31="","",Products!$F$28) | D31: =IF($A31="","",COUNTIFS(Library!$A$2:$A$401,$A31)) | E31: =IF($A31="","",COUNTIFS(Library!$A$2:$A$401,$A31,Library!$L$2:$L$401,"Yes")) | F31: =IF($A31="","",COUNTIFS(Library!$A$2:$A$401,$A31,Library!$G$2:$G$401,"Clinical trial")+COUNTIFS(Library!$A$2:$A$401,$A31,Library!$G$2:$G$401,"Extension study")) | G31: =IF($A31="","",COUNTIFS(Library!$A$2:$A$401,$A31,Library!$G$2:$G$401,"Registry / Real-world study")+COUNTIFS(Library!$A$2:$A$401,$A31,Library!$G$2:$G$401,"Natural history study")) | H31: =IF($A31="","",COUNTIFS(Library!$A$2:$A$401,$A31,Library!$G$2:$G$401,"Guideline / Consensus")+COUNTIFS(Library!$A$2:$A$401,$A31,Library!$G$2:$G$401,"Expert recommendation")) | I31: =IF($A31="","",COUNTIFS(Library!$A$2:$A$401,$A31,Library!$AE$2:$AE$401,"Internal use only")+COUNTIFS(Library!$A$2:$A$401,$A31,Library!$AE$2:$AE$401,"Confidential")) | J31: =IF($A31="","",IF(COUNTIFS(Library!$A$2:$A$401,$A31,Library!$Z$2:$Z$401,">0")=0,"",_xlfn.MINIFS(Library!$Z$2:$Z$401,Library!$A$2:$A$401,$A31))) | K31: =IF($A31="","",IF(COUNTIFS(Library!$A$2:$A$401,$A31,Library!$Z$2:$Z$401,">0")=0,"",_xlfn.MAXIFS(Library!$Z$2:$Z$401,Library!$A$2:$A$401,$A31)))
A32: =IF(Products!$A$29="","",Products!$A$29) | B32: =IF($A32="","",Products!$C$29) | C32: =IF($A32="","",Products!$F$29) | D32: =IF($A32="","",COUNTIFS(Library!$A$2:$A$401,$A32)) | E32: =IF($A32="","",COUNTIFS(Library!$A$2:$A$401,$A32,Library!$L$2:$L$401,"Yes")) | F32: =IF($A32="","",COUNTIFS(Library!$A$2:$A$401,$A32,Library!$G$2:$G$401,"Clinical trial")+COUNTIFS(Library!$A$2:$A$401,$A32,Library!$G$2:$G$401,"Extension study")) | G32: =IF($A32="","",COUNTIFS(Library!$A$2:$A$401,$A32,Library!$G$2:$G$401,"Registry / Real-world study")+COUNTIFS(Library!$A$2:$A$401,$A32,Library!$G$2:$G$401,"Natural history study")) | H32: =IF($A32="","",COUNTIFS(Library!$A$2:$A$401,$A32,Library!$G$2:$G$401,"Guideline / Consensus")+COUNTIFS(Library!$A$2:$A$401,$A32,Library!$G$2:$G$401,"Expert recommendation")) | I32: =IF($A32="","",COUNTIFS(Library!$A$2:$A$401,$A32,Library!$AE$2:$AE$401,"Internal use only")+COUNTIFS(Library!$A$2:$A$401,$A32,Library!$AE$2:$AE$401,"Confidential")) | J32: =IF($A32="","",IF(COUNTIFS(Library!$A$2:$A$401,$A32,Library!$Z$2:$Z$401,">0")=0,"",_xlfn.MINIFS(Library!$Z$2:$Z$401,Library!$A$2:$A$401,$A32))) | K32: =IF($A32="","",IF(COUNTIFS(Library!$A$2:$A$401,$A32,Library!$Z$2:$Z$401,">0")=0,"",_xlfn.MAXIFS(Library!$Z$2:$Z$401,Library!$A$2:$A$401,$A32)))
A33: =IF(Products!$A$30="","",Products!$A$30) | B33: =IF($A33="","",Products!$C$30) | C33: =IF($A33="","",Products!$F$30) | D33: =IF($A33="","",COUNTIFS(Library!$A$2:$A$401,$A33)) | E33: =IF($A33="","",COUNTIFS(Library!$A$2:$A$401,$A33,Library!$L$2:$L$401,"Yes")) | F33: =IF($A33="","",COUNTIFS(Library!$A$2:$A$401,$A33,Library!$G$2:$G$401,"Clinical trial")+COUNTIFS(Library!$A$2:$A$401,$A33,Library!$G$2:$G$401,"Extension study")) | G33: =IF($A33="","",COUNTIFS(Library!$A$2:$A$401,$A33,Library!$G$2:$G$401,"Registry / Real-world study")+COUNTIFS(Library!$A$2:$A$401,$A33,Library!$G$2:$G$401,"Natural history study")) | H33: =IF($A33="","",COUNTIFS(Library!$A$2:$A$401,$A33,Library!$G$2:$G$401,"Guideline / Consensus")+COUNTIFS(Library!$A$2:$A$401,$A33,Library!$G$2:$G$401,"Expert recommendation")) | I33: =IF($A33="","",COUNTIFS(Library!$A$2:$A$401,$A33,Library!$AE$2:$AE$401,"Internal use only")+COUNTIFS(Library!$A$2:$A$401,$A33,Library!$AE$2:$AE$401,"Confidential")) | J33: =IF($A33="","",IF(COUNTIFS(Library!$A$2:$A$401,$A33,Library!$Z$2:$Z$401,">0")=0,"",_xlfn.MINIFS(Library!$Z$2:$Z$401,Library!$A$2:$A$401,$A33))) | K33: =IF($A33="","",IF(COUNTIFS(Library!$A$2:$A$401,$A33,Library!$Z$2:$Z$401,">0")=0,"",_xlfn.MAXIFS(Library!$Z$2:$Z$401,Library!$A$2:$A$401,$A33)))
A34: =IF(Products!$A$31="","",Products!$A$31) | B34: =IF($A34="","",Products!$C$31) | C34: =IF($A34="","",Products!$F$31) | D34: =IF($A34="","",COUNTIFS(Library!$A$2:$A$401,$A34)) | E34: =IF($A34="","",COUNTIFS(Library!$A$2:$A$401,$A34,Library!$L$2:$L$401,"Yes")) | F34: =IF($A34="","",COUNTIFS(Library!$A$2:$A$401,$A34,Library!$G$2:$G$401,"Clinical trial")+COUNTIFS(Library!$A$2:$A$401,$A34,Library!$G$2:$G$401,"Extension study")) | G34: =IF($A34="","",COUNTIFS(Library!$A$2:$A$401,$A34,Library!$G$2:$G$401,"Registry / Real-world study")+COUNTIFS(Library!$A$2:$A$401,$A34,Library!$G$2:$G$401,"Natural history study")) | H34: =IF($A34="","",COUNTIFS(Library!$A$2:$A$401,$A34,Library!$G$2:$G$401,"Guideline / Consensus")+COUNTIFS(Library!$A$2:$A$401,$A34,Library!$G$2:$G$401,"Expert recommendation")) | I34: =IF($A34="","",COUNTIFS(Library!$A$2:$A$401,$A34,Library!$AE$2:$AE$401,"Internal use only")+COUNTIFS(Library!$A$2:$A$401,$A34,Library!$AE$2:$AE$401,"Confidential")) | J34: =IF($A34="","",IF(COUNTIFS(Library!$A$2:$A$401,$A34,Library!$Z$2:$Z$401,">0")=0,"",_xlfn.MINIFS(Library!$Z$2:$Z$401,Library!$A$2:$A$401,$A34))) | K34: =IF($A34="","",IF(COUNTIFS(Library!$A$2:$A$401,$A34,Library!$Z$2:$Z$401,">0")=0,"",_xlfn.MAXIFS(Library!$Z$2:$Z$401,Library!$A$2:$A$401,$A34)))
A35: =IF(Products!$A$32="","",Products!$A$32) | B35: =IF($A35="","",Products!$C$32) | C35: =IF($A35="","",Products!$F$32) | D35: =IF($A35="","",COUNTIFS(Library!$A$2:$A$401,$A35)) | E35: =IF($A35="","",COUNTIFS(Library!$A$2:$A$401,$A35,Library!$L$2:$L$401,"Yes")) | F35: =IF($A35="","",COUNTIFS(Library!$A$2:$A$401,$A35,Library!$G$2:$G$401,"Clinical trial")+COUNTIFS(Library!$A$2:$A$401,$A35,Library!$G$2:$G$401,"Extension study")) | G35: =IF($A35="","",COUNTIFS(Library!$A$2:$A$401,$A35,Library!$G$2:$G$401,"Registry / Real-world study")+COUNTIFS(Library!$A$2:$A$401,$A35,Library!$G$2:$G$401,"Natural history study")) | H35: =IF($A35="","",COUNTIFS(Library!$A$2:$A$401,$A35,Library!$G$2:$G$401,"Guideline / Consensus")+COUNTIFS(Library!$A$2:$A$401,$A35,Library!$G$2:$G$401,"Expert recommendation")) | I35: =IF($A35="","",COUNTIFS(Library!$A$2:$A$401,$A35,Library!$AE$2:$AE$401,"Internal use only")+COUNTIFS(Library!$A$2:$A$401,$A35,Library!$AE$2:$AE$401,"Confidential")) | J35: =IF($A35="","",IF(COUNTIFS(Library!$A$2:$A$401,$A35,Library!$Z$2:$Z$401,">0")=0,"",_xlfn.MINIFS(Library!$Z$2:$Z$401,Library!$A$2:$A$401,$A35))) | K35: =IF($A35="","",IF(COUNTIFS(Library!$A$2:$A$401,$A35,Library!$Z$2:$Z$401,">0")=0,"",_xlfn.MAXIFS(Library!$Z$2:$Z$401,Library!$A$2:$A$401,$A35)))
A36: =IF(Products!$A$33="","",Products!$A$33) | B36: =IF($A36="","",Products!$C$33) | C36: =IF($A36="","",Products!$F$33) | D36: =IF($A36="","",COUNTIFS(Library!$A$2:$A$401,$A36)) | E36: =IF($A36="","",COUNTIFS(Library!$A$2:$A$401,$A36,Library!$L$2:$L$401,"Yes")) | F36: =IF($A36="","",COUNTIFS(Library!$A$2:$A$401,$A36,Library!$G$2:$G$401,"Clinical trial")+COUNTIFS(Library!$A$2:$A$401,$A36,Library!$G$2:$G$401,"Extension study")) | G36: =IF($A36="","",COUNTIFS(Library!$A$2:$A$401,$A36,Library!$G$2:$G$401,"Registry / Real-world study")+COUNTIFS(Library!$A$2:$A$401,$A36,Library!$G$2:$G$401,"Natural history study")) | H36: =IF($A36="","",COUNTIFS(Library!$A$2:$A$401,$A36,Library!$G$2:$G$401,"Guideline / Consensus")+COUNTIFS(Library!$A$2:$A$401,$A36,Library!$G$2:$G$401,"Expert recommendation")) | I36: =IF($A36="","",COUNTIFS(Library!$A$2:$A$401,$A36,Library!$AE$2:$AE$401,"Internal use only")+COUNTIFS(Library!$A$2:$A$401,$A36,Library!$AE$2:$AE$401,"Confidential")) | J36: =IF($A36="","",IF(COUNTIFS(Library!$A$2:$A$401,$A36,Library!$Z$2:$Z$401,">0")=0,"",_xlfn.MINIFS(Library!$Z$2:$Z$401,Library!$A$2:$A$401,$A36))) | K36: =IF($A36="","",IF(COUNTIFS(Library!$A$2:$A$401,$A36,Library!$Z$2:$Z$401,">0")=0,"",_xlfn.MAXIFS(Library!$Z$2:$Z$401,Library!$A$2:$A$401,$A36)))
A37: =IF(Products!$A$34="","",Products!$A$34) | B37: =IF($A37="","",Products!$C$34) | C37: =IF($A37="","",Products!$F$34) | D37: =IF($A37="","",COUNTIFS(Library!$A$2:$A$401,$A37)) | E37: =IF($A37="","",COUNTIFS(Library!$A$2:$A$401,$A37,Library!$L$2:$L$401,"Yes")) | F37: =IF($A37="","",COUNTIFS(Library!$A$2:$A$401,$A37,Library!$G$2:$G$401,"Clinical trial")+COUNTIFS(Library!$A$2:$A$401,$A37,Library!$G$2:$G$401,"Extension study")) | G37: =IF($A37="","",COUNTIFS(Library!$A$2:$A$401,$A37,Library!$G$2:$G$401,"Registry / Real-world study")+COUNTIFS(Library!$A$2:$A$401,$A37,Library!$G$2:$G$401,"Natural history study")) | H37: =IF($A37="","",COUNTIFS(Library!$A$2:$A$401,$A37,Library!$G$2:$G$401,"Guideline / Consensus")+COUNTIFS(Library!$A$2:$A$401,$A37,Library!$G$2:$G$401,"Expert recommendation")) | I37: =IF($A37="","",COUNTIFS(Library!$A$2:$A$401,$A37,Library!$AE$2:$AE$401,"Internal use only")+COUNTIFS(Library!$A$2:$A$401,$A37,Library!$AE$2:$AE$401,"Confidential")) | J37: =IF($A37="","",IF(COUNTIFS(Library!$A$2:$A$401,$A37,Library!$Z$2:$Z$401,">0")=0,"",_xlfn.MINIFS(Library!$Z$2:$Z$401,Library!$A$2:$A$401,$A37))) | K37: =IF($A37="","",IF(COUNTIFS(Library!$A$2:$A$401,$A37,Library!$Z$2:$Z$401,">0")=0,"",_xlfn.MAXIFS(Library!$Z$2:$Z$401,Library!$A$2:$A$401,$A37)))
A38: =IF(Products!$A$35="","",Products!$A$35) | B38: =IF($A38="","",Products!$C$35) | C38: =IF($A38="","",Products!$F$35) | D38: =IF($A38="","",COUNTIFS(Library!$A$2:$A$401,$A38)) | E38: =IF($A38="","",COUNTIFS(Library!$A$2:$A$401,$A38,Library!$L$2:$L$401,"Yes")) | F38: =IF($A38="","",COUNTIFS(Library!$A$2:$A$401,$A38,Library!$G$2:$G$401,"Clinical trial")+COUNTIFS(Library!$A$2:$A$401,$A38,Library!$G$2:$G$401,"Extension study")) | G38: =IF($A38="","",COUNTIFS(Library!$A$2:$A$401,$A38,Library!$G$2:$G$401,"Registry / Real-world study")+COUNTIFS(Library!$A$2:$A$401,$A38,Library!$G$2:$G$401,"Natural history study")) | H38: =IF($A38="","",COUNTIFS(Library!$A$2:$A$401,$A38,Library!$G$2:$G$401,"Guideline / Consensus")+COUNTIFS(Library!$A$2:$A$401,$A38,Library!$G$2:$G$401,"Expert recommendation")) | I38: =IF($A38="","",COUNTIFS(Library!$A$2:$A$401,$A38,Library!$AE$2:$AE$401,"Internal use only")+COUNTIFS(Library!$A$2:$A$401,$A38,Library!$AE$2:$AE$401,"Confidential")) | J38: =IF($A38="","",IF(COUNTIFS(Library!$A$2:$A$401,$A38,Library!$Z$2:$Z$401,">0")=0,"",_xlfn.MINIFS(Library!$Z$2:$Z$401,Library!$A$2:$A$401,$A38))) | K38: =IF($A38="","",IF(COUNTIFS(Library!$A$2:$A$401,$A38,Library!$Z$2:$Z$401,">0")=0,"",_xlfn.MAXIFS(Library!$Z$2:$Z$401,Library!$A$2:$A$401,$A38)))
A39: =IF(Products!$A$36="","",Products!$A$36) | B39: =IF($A39="","",Products!$C$36) | C39: =IF($A39="","",Products!$F$36) | D39: =IF($A39="","",COUNTIFS(Library!$A$2:$A$401,$A39)) | E39: =IF($A39="","",COUNTIFS(Library!$A$2:$A$401,$A39,Library!$L$2:$L$401,"Yes")) | F39: =IF($A39="","",COUNTIFS(Library!$A$2:$A$401,$A39,Library!$G$2:$G$401,"Clinical trial")+COUNTIFS(Library!$A$2:$A$401,$A39,Library!$G$2:$G$401,"Extension study")) | G39: =IF($A39="","",COUNTIFS(Library!$A$2:$A$401,$A39,Library!$G$2:$G$401,"Registry / Real-world study")+COUNTIFS(Library!$A$2:$A$401,$A39,Library!$G$2:$G$401,"Natural history study")) | H39: =IF($A39="","",COUNTIFS(Library!$A$2:$A$401,$A39,Library!$G$2:$G$401,"Guideline / Consensus")+COUNTIFS(Library!$A$2:$A$401,$A39,Library!$G$2:$G$401,"Expert recommendation")) | I39: =IF($A39="","",COUNTIFS(Library!$A$2:$A$401,$A39,Library!$AE$2:$AE$401,"Internal use only")+COUNTIFS(Library!$A$2:$A$401,$A39,Library!$AE$2:$AE$401,"Confidential")) | J39: =IF($A39="","",IF(COUNTIFS(Library!$A$2:$A$401,$A39,Library!$Z$2:$Z$401,">0")=0,"",_xlfn.MINIFS(Library!$Z$2:$Z$401,Library!$A$2:$A$401,$A39))) | K39: =IF($A39="","",IF(COUNTIFS(Library!$A$2:$A$401,$A39,Library!$Z$2:$Z$401,">0")=0,"",_xlfn.MAXIFS(Library!$Z$2:$Z$401,Library!$A$2:$A$401,$A39)))
A40: =IF(Products!$A$37="","",Products!$A$37) | B40: =IF($A40="","",Products!$C$37) | C40: =IF($A40="","",Products!$F$37) | D40: =IF($A40="","",COUNTIFS(Library!$A$2:$A$401,$A40)) | E40: =IF($A40="","",COUNTIFS(Library!$A$2:$A$401,$A40,Library!$L$2:$L$401,"Yes")) | F40: =IF($A40="","",COUNTIFS(Library!$A$2:$A$401,$A40,Library!$G$2:$G$401,"Clinical trial")+COUNTIFS(Library!$A$2:$A$401,$A40,Library!$G$2:$G$401,"Extension study")) | G40: =IF($A40="","",COUNTIFS(Library!$A$2:$A$401,$A40,Library!$G$2:$G$401,"Registry / Real-world study")+COUNTIFS(Library!$A$2:$A$401,$A40,Library!$G$2:$G$401,"Natural history study")) | H40: =IF($A40="","",COUNTIFS(Library!$A$2:$A$401,$A40,Library!$G$2:$G$401,"Guideline / Consensus")+COUNTIFS(Library!$A$2:$A$401,$A40,Library!$G$2:$G$401,"Expert recommendation")) | I40: =IF($A40="","",COUNTIFS(Library!$A$2:$A$401,$A40,Library!$AE$2:$AE$401,"Internal use only")+COUNTIFS(Library!$A$2:$A$401,$A40,Library!$AE$2:$AE$401,"Confidential")) | J40: =IF($A40="","",IF(COUNTIFS(Library!$A$2:$A$401,$A40,Library!$Z$2:$Z$401,">0")=0,"",_xlfn.MINIFS(Library!$Z$2:$Z$401,Library!$A$2:$A$401,$A40))) | K40: =IF($A40="","",IF(COUNTIFS(Library!$A$2:$A$401,$A40,Library!$Z$2:$Z$401,">0")=0,"",_xlfn.MAXIFS(Library!$Z$2:$Z$401,Library!$A$2:$A$401,$A40)))
A41: =IF(Products!$A$38="","",Products!$A$38) | B41: =IF($A41="","",Products!$C$38) | C41: =IF($A41="","",Products!$F$38) | D41: =IF($A41="","",COUNTIFS(Library!$A$2:$A$401,$A41)) | E41: =IF($A41="","",COUNTIFS(Library!$A$2:$A$401,$A41,Library!$L$2:$L$401,"Yes")) | F41: =IF($A41="","",COUNTIFS(Library!$A$2:$A$401,$A41,Library!$G$2:$G$401,"Clinical trial")+COUNTIFS(Library!$A$2:$A$401,$A41,Library!$G$2:$G$401,"Extension study")) | G41: =IF($A41="","",COUNTIFS(Library!$A$2:$A$401,$A41,Library!$G$2:$G$401,"Registry / Real-world study")+COUNTIFS(Library!$A$2:$A$401,$A41,Library!$G$2:$G$401,"Natural history study")) | H41: =IF($A41="","",COUNTIFS(Library!$A$2:$A$401,$A41,Library!$G$2:$G$401,"Guideline / Consensus")+COUNTIFS(Library!$A$2:$A$401,$A41,Library!$G$2:$G$401,"Expert recommendation")) | I41: =IF($A41="","",COUNTIFS(Library!$A$2:$A$401,$A41,Library!$AE$2:$AE$401,"Internal use only")+COUNTIFS(Library!$A$2:$A$401,$A41,Library!$AE$2:$AE$401,"Confidential")) | J41: =IF($A41="","",IF(COUNTIFS(Library!$A$2:$A$401,$A41,Library!$Z$2:$Z$401,">0")=0,"",_xlfn.MINIFS(Library!$Z$2:$Z$401,Library!$A$2:$A$401,$A41))) | K41: =IF($A41="","",IF(COUNTIFS(Library!$A$2:$A$401,$A41,Library!$Z$2:$Z$401,">0")=0,"",_xlfn.MAXIFS(Library!$Z$2:$Z$401,Library!$A$2:$A$401,$A41)))
...

Sheet Products
A1: Product | B1: Generic Name | C1: Therapy Area | D1: Indication | E1: Company | F1: Own / Competitor | G1: Status | H1: Notes
A2: Vimizim | B2: elosulfase alfa | C2: MPS | D2: MPS IVA (Morquio A) | E2: BioMarin | F2: Own | G2: Approved
A3: Naglazyme | B3: galsulfase | C3: MPS | D3: MPS VI (Maroteaux-Lamy) | E3: BioMarin | F3: Own | G3: Approved
A4: Vimizim + Naglazyme | B4: elosulfase alfa / galsulfase | C4: MPS | D4: MPS IVA and MPS VI | E4: BioMarin | F4: Own | G4: Approved | H4: Use for references that cover both products
A5: MPS (general) | C5: MPS | D5: Mucopolysaccharidoses (several types) | F5: N/A | H5: Use for disease-level references not tied to one product
A6: Brineura | B6: cerliponase alfa | C6: CLN2 | D6: CLN2 disease (TPP1 deficiency) | E6: BioMarin | F6: Own | G6: Approved
A7: Voxzogo | B7: vosoritide | C7: Achondroplasia | D7: Achondroplasia | E7: BioMarin | F7: Own | G7: Approved
A8: Palynziq | B8: pegvaliase | C8: PKU | D8: Phenylketonuria | E8: BioMarin | F8: Own | G8: Approved

Sheet Lists
A1: Therapy Area | B1: Record Type | C1: Phase | D1: Pivotal | E1: Status | F1: Own / Competitor | G1: Confidentiality | H1: Study Design
A2: MPS | B2: Clinical trial | C2: Phase 1 | D2: Yes | E2: Not yet recruiting | F2: Own | G2: Public | H2: Randomized, double-blind, placebo-controlled
A3: CLN2 | B3: Extension study | C3: Phase 1/2 | D3: No | E3: Recruiting | F3: Competitor | G3: Internal use only | H3: Randomized, double-blind (dose comparison)
A4: Achondroplasia | B4: Natural history study | C4: Phase 2 | E4: Active, not recruiting | F4: N/A | G4: Confidential | H4: Randomized, open-label
A5: PKU | B5: Registry / Real-world study | C5: Phase 2/3 | E5: Completed | H5: Single-arm, open-label
B6: Guideline / Consensus | C6: Phase 3 | E6: Terminated | H6: Open-label extension
B7: Expert recommendation | C7: Phase 4 | E7: Withdrawn | H7: Single-patient / case report
B8: Review | C8: Not applicable | E8: Suspended | H8: Observational / Registry
B9: Internal material | E9: Published | H9: Delphi / expert panel
E10: Unknown | H10: Other
A22: Edit these lists to change the dropdown options.
