Workbook

Sheet Summary
A1: CPG/DMT-A/332 – Guidelines for the Diagnosis, Management and Treatment of Children with Achondroplasia
A2: Comparison of the updated draft against the 2024 version
B4: Updated version (left side) | C4: Manual-CPG Achondroplasia 332 (.docx). Draft, effective / revision dates not yet filled in.
B5: Old version (right side) | C5: Manua-CPG Achondroplasia 332 (PDF). Effective 27/08/24, revision due 26/08/26.
B6: Main sources of change | C6: EU SmPC rev. 10/2023 (ref 6), FDA all-ages approval Oct 2023 (ref 11), Middle East consensus 2026 (ref 12), international vosoritide consensus 2025 (ref 13).
B8: Change count (live from the sheets)
B9: Status | C9: Main text | D9: Dosing table | E9: Monitoring | F9: References | G9: Meaning
B10: New | C10: =COUNTIF('Side-by-Side Comparison'!$F$5:$F$78,B10) -> 20 | D10: =COUNTIF('Dosing Table 12.1'!$N$5:$N$15,B10) -> 3 | E10: =COUNTIF('Monitoring Schedule'!$G$5:$G$19,B10) -> 3 | F10: =COUNTIF(References!$F$5:$F$24,B10) -> 9 | G10: Added in the update. Not in 2024.
B11: Modified | C11: =COUNTIF('Side-by-Side Comparison'!$F$5:$F$78,B11) -> 15 | D11: =COUNTIF('Dosing Table 12.1'!$N$5:$N$15,B11) -> 1 | E11: =COUNTIF('Monitoring Schedule'!$G$5:$G$19,B11) -> 7 | F11: =COUNTIF(References!$F$5:$F$24,B11) -> 1 | G11: In both versions, but the content changed.
B12: Removed | C12: =COUNTIF('Side-by-Side Comparison'!$F$5:$F$78,B12) -> 2 | D12: =COUNTIF('Dosing Table 12.1'!$N$5:$N$15,B12) -> 0 | E12: =COUNTIF('Monitoring Schedule'!$G$5:$G$19,B12) -> 4 | F12: =COUNTIF(References!$F$5:$F$24,B12) -> 1 | G12: In 2024, dropped from the update.
B13: Unchanged | C13: =COUNTIF('Side-by-Side Comparison'!$F$5:$F$78,B13) -> 28 | D13: =COUNTIF('Dosing Table 12.1'!$N$5:$N$15,B13) -> 7 | E13: =COUNTIF('Monitoring Schedule'!$G$5:$G$19,B13) -> 1 | F13: =COUNTIF(References!$F$5:$F$24,B13) -> 5 | G13: Same in both versions.
B14: Renumbered | C14: =COUNTIF('Side-by-Side Comparison'!$F$5:$F$78,B14) -> 0 | D14: =COUNTIF('Dosing Table 12.1'!$N$5:$N$15,B14) -> 0 | E14: =COUNTIF('Monitoring Schedule'!$G$5:$G$19,B14) -> 0 | F14: =COUNTIF(References!$F$5:$F$24,B14) -> 4 | G14: Same content, new number (references only).
B15: Total | C15: =SUM(C10:C14) -> 65 | D15: =SUM(D10:D14) -> 11 | E15: =SUM(E10:E14) -> 15 | F15: =SUM(F10:F14) -> 20
B17: Key changes at a glance
A18: 1 | B18: Indication updated (5.3.1): EU label now starts at 4 months (was 2 years). FDA now covers all ages with open growth plates (was 5 years and over).
A19: 2 | B19: Stopping rule changed (5.4): was AGV <1.5 cm after 1 year OR closed plates. Now AGV <1.5 cm/year AND radiologically closed plates. In practice, treatment will run longer.
A20: 3 | B20: Exclusion list shortened (5.3.3): the 'poor response after 1 year' and 'non-compliant' exclusions were dropped.
A21: 4 | B21: New 5.3.5 'Dose, units and administration' (from the SmPC): µg/kg range, mL↔Units, weight-band review every 3–6 months, missed-dose rule, site rotation, caregiver training, and a first dose in clinic with ~1 h observation.
A22: 5 | B22: Dosing table 12.1 now starts at 4 kg (was 10 kg). This closes a real gap for infants under 10 kg. Doses at 10 kg and above are the same.
A23: 6 | B23: Hypotension advice aligned with the SmPC: light snack + fluids about 30 minutes before the injection (was a meal + 8–10 oz within 1 hour).
A24: 7 | B24: New safety text: hypersensitivity contraindication, avoid in pregnancy and breast-feeding, no driving/cycling for 60 minutes after the injection.
A25: 8 | B25: Monitoring restructured: new baseline checklist (5.5.4, 8 domains) and an age-based follow-up table (5.5.5). Infants (0–2 y) are now seen every 3 months.
A26: 9 | B26: New content from the Middle East consensus: prenatal diagnosis (5.1 D), routine infant craniocervical MRI and polysomnography, a formal MDT with a care coordinator, shared decision-making, QoL tools and a transition clinic.
A27: 10 | B27: References grew from 11 to 19: 9 new sources added (2023–2026), one duplicate removed, and the SmPC citation now in full.
B29: Points for the committee before sign-off
A30: 1 | B30: Delete the old 2024 dosing table (still shown in red in the draft) so there's only one dosing table in the final document.
A31: 2 | B31: Bring appendix 11.20 in line with the new 5.5.5 schedule, or point 5.5 to 5.5.5. Right now they give different visit intervals for infants.
A32: 3 | B32: Confirm on purpose that a child who isn't responding (AGV <1.5 cm/year) but still has open growth plates should keep going. The old one-year non-responder rule is gone, and nothing replaces it.
A33: 4 | B33: Concomitant medications and vitamin D no longer have a follow-up interval. Consider adding both to the 5.5.5 table.
A34: 5 | B34: Refs 4 and 5 are still in the list but aren't cited any more, and they describe the old age limits. Consider removing them. Ref 10 (chegg.com) isn't a peer-reviewed source.
A35: 6 | B35: Update the clinical algorithm (section 6) to show the prenatal pathway, infant MRI and sleep-study screening, and the shared decision-making step.
A36: 7 | B36: Fill in the CPG history (replaces the 2024 version, new effective and revision dates) and the approval signature dates.
A37: 8 | B37: Fix two typos carried over from 2024: 'dipropionate' → 'disproportionate' (2.1), and 'Legible' → 'Eligible' (5.3.2 a).
A38: 9 | B38: Check service capacity before go-live: routine infant MRI and polysomnography, first-dose observation slots, and specialist-nurse training for caregivers.
B40: How to read this workbook
B41: Side-by-Side Comparison | C41: The full guideline, section by section. Updated text on the left, 2024 text on the right, comparison columns at the end. Filter the Status column to see only what changed.
B42: Dosing Table 12.1 | C42: Weight bands in the new and old tables, lined up side by side.
B43: Monitoring Schedule | C43: The new 5.5.5 follow-up table against the 2024 appendix 11.20 timings.
B44: References | C44: Both reference lists lined up: added, removed, renumbered, and where each is cited.
B46: Colour key: blue = updated version · brown/peach = 2024 version · pink = new · yellow = modified · red = removed · green = unchanged · light blue = renumbered.

Sheet Side-by-Side Comparison
A1: CPG/DMT-A/332 – Achondroplasia: Updated version vs 2024 version
A2: Left = UPDATED draft (Manual-CPG Achondroplasia 332, .docx). Right = OLD version (Manua-CPG Achondroplasia 332, PDF, effective 27/08/24). Comparison columns explain what changed and why it matters. Use the filter on 'Status' to show only New / Modified / Removed items.
A3: UPDATED VERSION (draft) | D3: OLD VERSION (2024) | F3: COMPARISON
A4: Section (updated) | B4: Topic | C4: Updated text | D4: Old text (2024) | E4: Section (old) | F4: Status | G4: What changed / why it matters | H4: References (old → new)
A5: 1. Introduction & 2. Definitions
A6: 1 | B6: Introduction | C6: Achondroplasia is the most common form of skeletal dysplasia. It's inherited as a Mendelian autosomal dominant trait with complete penetrance. Approximately 80% of cases are due to a new (de novo) dominant mutation. The frequency is believed to be 1 case per 15,000-40,000 births worldwide, with an average worldwide frequency of 1 in 25,000 live births. (1) The prevalence of Achondroplasia is 1:26,000-1:28,000 live births. (2) The condition is caused by a common, recurring, gain-of-function mutation in FGFR3, the gene that encodes fibroblast growth factor receptor 3. This mutation leads to impaired endochondral ossification of the human skeleton. (3) • Average adult height 4 feet. • Male average adult height 131 ± 5.6 cm. • Female average adult height 124 ± 5.9 cm. | D6: Achondroplasia is the most common form of skeletal dysplasia. It's inherited as a Mendelian autosomal dominant trait with complete penetrance. Approximately 80% of cases are due to a new (de novo) dominant mutation. The frequency is believed to be 1 case per 15,000-40,000 births worldwide, with an average worldwide frequency of 1 in 25,000 live births. (1) The prevalence of Achondroplasia is 1:26,000-1:28,000 live births. (2) The condition is caused by a common, recurring, gain-of-function mutation in FGFR3, the gene that encodes fibroblast growth factor receptor 3. This mutation leads to impaired endochondral ossification of the human skeleton. (3) • Average adult height 4 feet. • Male average adult height 131 ± 5.6 cm. • Female average adult height 124 ± 5.9 cm. | E6: 1 | F6: Unchanged | G6: Word-for-word the same as 2024. | H6: Refs 1–3 (same in both)
A7: 2.1 | B7: Definition – Achondroplasia | C7: Achondroplasia: is the most common dipropionate short stature characterized by a variety of medical, functional, and psychosocial challenges across the lifespan that require care from a multidisciplinary team. Affected individuals have rhizomelic shortening of the limbs, macrocephaly, and characteristic facial features with frontal bossing and midface retrusion. In infancy, hypotonia is typical, and acquisition of developmental motor milestones is often both aberrant in pattern and delayed. Intelligence and life span are usually near normal, although craniocervical junction compression increases the risk of death in infancy. Additional complications include obstructive sleep apnea, middle ear dysfunction, kyphosis, and spinal stenosis. (2,3) | D7: Achondroplasia: is the most common dipropionate short stature characterized by a variety of medical, functional, and psychosocial challenges across the lifespan that require care from a multidisciplinary team. Affected individuals have rhizomelic shortening of the limbs, macrocephaly, and characteristic facial features with frontal bossing and midface retrusion. In infancy, hypotonia is typical, and acquisition of developmental motor milestones is often both aberrant in pattern and delayed. Intelligence and life span are usually near normal, although craniocervical junction compression increases the risk of death in infancy. Additional complications include obstructive sleep apnea, middle ear dysfunction, kyphosis, and spinal stenosis. (2,3) | E7: 2.1 | F7: Unchanged | G7: Same text. Typo carried over from 2024: "dipropionate" should read "disproportionate". | H7: Refs 2,3
A8: 2.2 | B8: Definition – Trident hand | C8: Trident hand: The hand with increased distance between the 3rd and 4th fingers. | D8: Trident hand: The hand with increased distance between the 3rd and 4th fingers. | E8: 2.2 | F8: Unchanged | G8: — | H8: —
A9: 2.3 | B9: Definition – AGV | C9: AGV (Annualized Growth Velocity) refers to the equivalent average rate of growth per annum that will give us the same growth rate as that observed over the entire time span. | D9: AGV (Annualized Growth Velocity) refers to the equivalent average rate of growth per annum that will give us the same growth rate as that observed over the entire time span. | E9: 2.3 | F9: Unchanged | G9: — | H9: —
A10: 3. Scope & Purpose | 4. Target Population
A11: 3 | B11: Scope and purpose | C11: Scope: This Guidelines is designed for the diagnosis and management of pediatric cases in KSMC who are suspected and diagnosed to have achondroplasia. Purpose: • To have a basic Guidelines for the geneticist, pediatric endocrinologist, and other multidisciplinary healthcare providers. • To standardize the diagnosis and management for the affected children with Achondroplasia. | D11: Scope: This Guidelines is designed for the diagnosis and management of pediatric cases in KSMC who are suspected and diagnosed to have achondroplasia. Purpose: • To have a basic Guidelines for the geneticist, pediatric endocrinologist, and other multidisciplinary healthcare providers. • To standardize the diagnosis and management for the affected children with Achondroplasia. | E11: 3 | F11: Unchanged | G11: — | H11: —
A12: 4 | B12: Target population | C12: • Suspected cases with achondroplasia from age 0-18 years. • Achondroplasia cases who are eligible for Vosoritide treatment from 4 months to 10 years of age. • Achondroplasia cases already on treatment. | D12: • Suspected cases with achondroplasia from age 0-18 years. • Achondroplasia cases who are eligible for Vosoritide treatment from 4 months to 10 years of age. • Achondroplasia cases already on treatment. | E12: 4 | F12: Unchanged | G12: Treatment window kept at 4 months–10 years. Worth noting that 5.3.1 now quotes the FDA approval for all ages with open growth plates, so the local 10-year cut-off is a KSMC policy choice rather than a label limit – the committee may want to state that explicitly. | H12: —
A13: 5.1 Diagnostic Method
A14: 5.1 A | B14: Clinical findings | C14: Figure retained: disproportionate short stature, short fingers, trident hand. | D14: Figure: disproportionate short stature, short fingers, trident hand. | E14: 5.1 A | F14: Unchanged | G14: Same images. | H14: —
A15: 5.1 B | B15: Radiological | C15: Radiological figure retained (lumbar inter-pediculate narrowing, square iliac wings, narrow sciatic notches, thoracolumbar kyphosis, short tubular bones with metaphyseal widening, trident hand, frontal bossing / small skull base). | D15: Same radiological figure. | E15: 5.1 B | F15: Unchanged | G15: Same images. | H15: —
A16: 5.1 C | B16: Molecular testing | C16: • Targeted gene testing for the FGFR3 (Fibroblast growth factor receptor3) gene. | D16: • Targeted gene testing for the FGFR3 (Fibroblast growth factor receptor3) gene. | E16: 5.1 C | F16: Unchanged | G16: — | H16: —
A17: 5.1 D | B17: Prenatal diagnosis (NEW sub-section) | C17: Prenatal diagnosis by ultrasound and molecular testing should be offered when there is clinical suspicion or a positive family history; typical ultrasound features (rhizomelic limb shortening, macrocephaly with frontal bossing and midface hypoplasia) often become apparent after 24 weeks of gestation. Counselling should be clear and non-directive, providing balanced, evidence-based information, including education on safe positioning and handling of infants with achondroplasia. Parents who receive a prenatal diagnosis should be offered early psychological support and education (12). | D17: — Not addressed in this version — | E17: — | F17: New | G17: Brand-new sub-section. Brings in the prenatal pathway: when to offer US + molecular testing, the >24-week timing of US signs, non-directive counselling, and early psychological support for parents. | H17: New ref 12 (Middle East consensus 2026)
A18: 5.2 Multi-System Co-Morbidities
A19: 5.2 | B19: Co-morbidities figure | C19: Figure retained: ENT, cardiopulmonary, extremities, nervous system, back, obesity. | D19: Figure: ENT (otitis media, hearing loss, dental malocclusion); cardiopulmonary (sleep-disordered breathing, CVD); extremities; nervous system (foramen magnum stenosis, hydrocephalus, cervicomedullary compression); back; obesity. | E19: 5.2 | F19: Unchanged | G19: Same figure. | H19: —
A20: 5.2 | B20: Screening in infancy (NEW) | C20: Screening in infancy: where available and clinically feasible, MRI of the craniocervical junction should be offered routinely in early infancy to screen for foramen magnum stenosis, with reports using standardised radiological scoring systems. Polysomnography should be performed routinely to detect sleep-disordered breathing, including central sleep apnoea, which may not be reliably identified on clinical assessment alone. Where these services are limited, clinicians should keep a low threshold for referral to a specialist centre. Regular screening and surveillance should continue for foramen magnum stenosis, sleep apnoea, ENT problems, neurological issues, orthopaedic complications and obesity (12). | D20: Not stated as a recommendation. The 2024 version only showed the co-morbidity figure; MRI brain / whole-spine MRI appeared only inside the clinical algorithm (section 6). | E20: 5.2 / 6 | F20: New | G20: Moves from "show the risks" to "actively screen": routine craniocervical MRI and routine polysomnography in infancy, with standardised MRI scoring and a referral route when local services are limited. Resource impact (MRI + sleep-lab capacity) should be checked. | H20: New ref 12
A21: 5.2 | B21: Multidisciplinary care (NEW) | C21: Multidisciplinary care: management should involve a multidisciplinary team, ideally including a paediatric endocrinologist, geneticist, orthopaedic surgeon, pulmonologist (for sleep studies), neurologist/neurosurgeon, physiotherapist, dentist/orthodontist, audiologist, psychologist, dietitian and occupational therapist. A multidisciplinary care coordinator or lead clinician should be designated to ensure continuous care, effective communication and follow-up across specialties. Surgical interventions should only be performed by clinicians with expertise in achondroplasia, with decisions made in conjunction with the multidisciplinary team (12). | D21: MDT listed only in the algorithm box: ENT, sleep-apnea specialist, orthodontist, orthopedic, spinal surgery, neurosurgery, dietitian, physiotherapy. | E21: 6 (algorithm) | F21: New | G21: MDT is now a formal recommendation. Adds pulmonologist, neurologist, dentist, audiologist, psychologist and occupational therapist; requires a named care coordinator / lead clinician; restricts surgery to clinicians with achondroplasia expertise. | H21: New ref 12
A22: 5.3 Treatment – Vosoritide
A23: 5.3.1 | B23: Vosoritide "Voxzogo" – indication | C23: The first and only therapy approved to increase linear growth in children with achondroplasia is called Vosoritide "Voxzogo". In the European Union, vosoritide is indicated for the treatment of achondroplasia in patients 4 months of age and older whose epiphyses are not closed, (6) and the US FDA has approved it (October 2023) to increase linear growth in paediatric patients of all ages with achondroplasia and open epiphyses. (11) Vosoritide is given as a single daily dose of subcutaneous injection to prevent the inhibition of chondrocyte mineralization resulting from FGFR3 mutation and allows linear bone growth. Treatment should be initiated and directed by a physician appropriately qualified in the management of growth disorders or skeletal dysplasias. Safety and efficacy data in children younger than 4 months are limited, and no posology recommendation can be made for this group (6). | D23: The first and only therapy approved to increase linear growth in children with achondroplasia is called Vosoritide "Voxzogo". In the European Union, vosoritide is indicated for the treatment of achondroplasia in children 2 years of age and older whose epiphyses are not closed, (4,5) and for children with achondroplasia 5 years and older by the American FDA. (6) Vosoritide is given as a single daily dose of subcutaneous injection to prevent the inhibition of chondrocyte mineralization resulting from FGFR3 mutation and allows linear bone growth. The diagnosis of achondroplasia should be confirmed by appropriate genetic testing. | E23: 5.3.1 | F23: Modified | G23: • EU indication: from 2 years → from 4 months. • FDA indication: 5 years and older → all ages with open epiphyses (Oct 2023). • Added: treatment must be started and directed by a physician qualified in growth disorders / skeletal dysplasia. • Added: no dosing recommendation below 4 months. • Removed: the sentence "diagnosis should be confirmed by appropriate genetic testing" (still required under 5.3.2 inclusion, so the intent survives). Note: the 2024 text was internally inconsistent (label from 2 y but local start from 4 months) – the update fixes this. | H23: Old (4,5) & (6) → New (6) SmPC & (11) FDA release
A24: 5.3.2 | B24: Inclusion – follow-up & start age | C24: • Follow up of achondroplasia cases aged 0-18 years whose clinical and radiological finding go with Achondroplasia. • Vosoritide treatment will be started for selected cases from 4 months to 10 years of age whose diagnosis had been confirmed by molecular testing, since the earlier the start of treatment (≤10 years of age) the better the outcome. | D24: • Follow up of achondroplasia cases aged 0-18 years whose clinical and radiological finding go with Achondroplasia. • Vosoritide treatment will be started for selected cases from 4 months to 10 years of age whose diagnosis had been confirmed by molecular testing, since the earlier the start of treatment (≤10 years of age) the better the outcome. | E24: 5.3.2 | F24: Unchanged | G24: — | H24: —
A25: 5.3.2 | B25: Inclusion – treatment indicated for (a, c, d) | C25: a) Legible children for expensive treatment of achondroplasia (Saudi nationality). c) Achondroplasia children with normal cognitive function. d) Compliant to treatment. | D25: a) Legible children for expensive treatment of achondroplasia (Saudi nationality). c) Achondroplasia children with normal cognitive function. d) Compliant to treatment. | E25: 5.3.2 | F25: Unchanged | G25: Same. Typo carried over: "Legible" should read "Eligible". | H25: —
A26: 5.3.2 b | B26: Inclusion – duration of treatment | C26: b) Achondroplasia cases from 4 months to 10 years of age and to be continued up to 18 years of age or until the stopping criteria in 5.4 are met, regardless of gender. | D26: b) Achondroplasia cases from 4 months to 10 years of age and to be continued up to 18 years of age or until AGV is <1.5 cm, regardless of gender. | E26: 5.3.2 b | F26: Modified | G26: "until AGV is <1.5 cm" replaced by a cross-reference to the stopping criteria in 5.4, so there is now one single stopping rule in the document. | H26: —
A27: 5.3.2 | B27: Considerations to identify patients (figure) | C27: Figure retained. | D27: Figure: genetically confirmed achondroplasia; open growth plates; age of patient; evidence of compliance with medical care; comprehensive assessment at initial encounter to follow-up; patient & family willingness to commit to daily injections, regular follow-up, frequent communication with the team and prompt reporting of side effects. | E27: 5.3.2 | F27: Unchanged | G27: Same figure. | H27: —
A28: 5.3.3 (1) | B28: Exclusion – age >10 y at diagnosis | C28: 1. Vosoritide treatment will not be applicable for Achondroplasia cases who already > 10 years at the time of the diagnosis. | D28: 1. Vosoritide treatment will not be applicable for Achondroplasia cases who already > 10 years at the time of the diagnosis. | E28: 5.3.3 (1) | F28: Unchanged | G28: — | H28: —
A29: — | B29: Exclusion – poor response after 1 year | C29: Removed from the exclusion list. | D29: 2. Achondroplasia cases whose annual growth velocity is < 1.5 cm after completing one year of vosoritide treatment. | E29: 5.3.3 (2) | F29: Removed | G29: Clinically important. In 2024 a child with AGV <1.5 cm after one year on treatment was excluded (non-responder rule). This is no longer in the exclusion list, and the new stopping rule in 5.4 needs BOTH low AGV and closed growth plates. Net effect: there is no longer an explicit rule to stop a non-responder whose growth plates are still open. Committee should confirm this is intended. | H29: —
A30: 5.3.3 (2) | B30: Exclusion – neurological insult | C30: 2. Achondroplasia cases who sustained significant neurological insult that affect their cognitive function. | D30: 3. Achondroplasia cases who sustained significant neurological insult that affect their cognitive function. | E30: 5.3.3 (3) | F30: Unchanged | G30: Same wording, renumbered 3 → 2. | H30: —
A31: — | B31: Exclusion – non-compliance | C31: Removed from the exclusion list. | D31: 4. Achondroplasia cases who are not compliant to treatment. | E31: 5.3.3 (4) | F31: Removed | G31: Dropped as an exclusion. Compliance is still an inclusion requirement (5.3.2 d), so it's partly covered – but there's no longer an explicit rule for what happens if a patient becomes non-compliant on treatment. | H31: —
A32: 5.3.3 (3) | B32: Exclusion – no regular MDT follow-up | C32: 3. Achondroplasia cases who don't attend regular follow up of the multidisciplinary team care. | D32: 5. Achondroplasia cases who don't attend regular follow up of the multidisciplinary team care. | E32: 5.3.3 (5) | F32: Unchanged | G32: Same wording, renumbered 5 → 3. | H32: —
A33: 5.3.3 | B33: Shared decision-making (NEW) | C33: Shared decision-making: decisions to start vosoritide should be individualised and made jointly with the family, taking into account the available evidence, treatment burden, family preferences, and cultural, financial and healthcare-system considerations (12). | D33: — Not addressed in this version — | E33: — | F33: New | G33: Adds a formal shared decision-making step with the family before starting treatment. | H33: New ref 12
A34: 5.3.4 | B34: Side effect – hypotension & pre-dose advice | C34: A temporary decrease in blood pressure in some patients. To reduce the risk of a decrease in blood pressure and associated symptoms, patients should be well hydrated, eat a light snack and drink an adequate amount of fluid (e.g., water, milk or juice) about 30 minutes before injecting (6). | D34: A temporary decrease in blood pressure in some patients. To reduce the risk of a decrease in blood pressure and associated symptoms, patients should eat a meal and drink 8 to 10 ounces of fluid within 1 hour before receiving Vosoritide. | E34: 5.3.4 | F34: Modified | G34: Pre-dose advice aligned with the EU SmPC: "a meal + 8–10 oz fluid within 1 hour" → "well hydrated, light snack and adequate fluid about 30 minutes before". Patient/caregiver leaflets should be updated to match. | H34: Uncited → ref 6 (SmPC)
... A45: 5.4 | B45: When to stop Vosoritide | C45: It should be discontinued upon confirmation of no further growth potential, indicated by an annual growth velocity of <1.5 cm/year and radiological confirmation of closed growth plates (epiphyses) (6). | D45: It should be discontinued for Achondroplasia cases whose annual growth velocity is <1.5 cm after completing one year of vosoritide treatment or upon radiological confirmation of no further growth potential, when growth plates are closed. | E45: 5.4 | F45: Modified | G45: Key change: the old rule was AGV <1.5 cm after 1 year OR closed plates (either one is enough). The new rule is AGV <1.5 cm/year AND radiological closed plates (both needed), in line with the SmPC. Treatment will therefore usually run longer. See also the removed exclusion criterion (non-responder after 1 year). | H45: Uncited → ref 6 (SmPC)
A46: 5.5 Monitoring & Follow-up
A47: 5.5 | B47: Monitoring heading | C47: Monitoring and follow-up protocols (See appendix 11.20) | D47: Monitoring and follow-up protocols (See appendix 11.20) | E47: 5.5 | F47: Unchanged | G47: Still points to appendix 11.20 (the 2024 timing table), while the new 5.5.5 table gives a different schedule. Suggest pointing to 5.5.5 as the main schedule, or updating 11.20, so staff aren't working from two different timetables. | H47: —
A48: 5.5.1 | B48: Treatment-informing assessments | C48: • Parental height considerations • Annual skeletal survey for evaluation of growth plate and bone age • Vitamin D level | D48: • Parental height considerations • Tanner staging • Bone age • Annual skeletal survey for evaluation of growth plate • Vitamin D level | E48: 5.5.1 | F48: Modified | G48: "Tanner staging" removed from this list (now in the baseline table 5.5.4 and from ~8 years in the follow-up table 5.5.5). "Bone age" merged into the annual skeletal survey line. | H48: —
A49: 5.5.2 | B49: Efficacy assessments | C49: • Anthropometrics (standing and sitting height, height, arm span, flexion and contractures, upper and lower arm segment) [shown in red as "Old (2024)"] • Symptoms (headaches, vision changes, worsening joint pain) | D49: • Anthropometrics (standing and sitting height, height, arm span, flexion and contractures, upper and lower arm segment) • Annualized growth velocity • Symptoms (headaches, vision changes, worsening joint pain) | E49: 5.5.2 | F49: Modified | G49: "Annualized growth velocity" bullet removed here – it now sits in the follow-up table 5.5.5 (from month 6, then every visit). Anthropometrics and symptoms kept. | H49: —
A50: 5.5.3 | B50: Safety assessment | C50: • Discussion of other intervention | D50: • Review adverse events • Discussion of concomitant/new medications • Discussion of other intervention | E50: 5.5.3 | F50: Modified | G50: Two bullets dropped. Adverse-event review is now covered every visit in 5.5.5. Concomitant medications are reviewed at baseline (5.5.4) but no longer appear anywhere in the follow-up schedule – worth adding back to 5.5.5. | H50: —
...

Sheet Dosing Table 12.1
A1: Table 12.1 – Vosoritide dose by body weight: updated vs 2024
A2: Updated = SmPC Table 1 (ref 6). Old = 2024 'Vosoretide Treatment (BioMarin)'. Frequency is once daily in both. Bands lined up on the same row where they cover the same weights.
A3: UPDATED (SmPC Table 1) | H3: OLD (2024) | N3: COMPARISON
A4: Body weight (kg) | B4: Dose | C4: Vial strength | D4: Solvent; concentration | E4: Volume (mL) | F4: Volume (Units) | H4: Body weight | I4: Dose | J4: Vial strength | K4: Concentration | L4: Volume (mL) | M4: Volume (Units) | N4: Status | O4: Comment
A5: 4 | B5: 0.12 mg | C5: 0.4 mg | D5: 0.5 mL; 0.8 mg/mL | E5: 0.15 mL | F5: 15 U | H5: — no band — | N5: New | O5: No 2024 dose for a 4 kg infant.
A6: 5 | B6: 0.16 mg | C6: 0.4 mg | D6: 0.5 mL; 0.8 mg/mL | E6: 0.20 mL | F6: 20 U | H6: — no band — | N6: New | O6: No 2024 dose for a 5 kg infant.
A7: 6–7 | B7: 0.20 mg | C7: 0.4 mg | D7: 0.5 mL; 0.8 mg/mL | E7: 0.25 mL | F7: 25 U | H7: — no band — | N7: New | O7: No 2024 dose for 6–7 kg.
A8: 8–11 | B8: 0.24 mg | C8: 0.4 mg | D8: 0.5 mL; 0.8 mg/mL | E8: 0.30 mL | F8: 30 U | H8: 10 to <12 kg | I8: 0.24 mg | J8: 0.4 mg/vial | K8: 0.8 mg/mL | L8: 0.3 mL | M8: 30 U | N8: Modified | O8: Same dose (0.24 mg / 30 U). Lower edge moved from 10 kg down to 8 kg.
A9: 12–16 | B9: 0.28 mg | C9: 0.56 mg | D9: 0.7 mL; 0.8 mg/mL | E9: 0.35 mL | F9: 35 U | H9: 12 to <17 kg | I9: 0.28 mg | J9: 0.56 mg/vial | K9: 0.8 mg/mL | L9: 0.35 mL | M9: 35 U | N9: Unchanged | O9: Same dose and volume; band label written as 12–16 instead of 12 to <17.
A10: 17–21 | B10: 0.32 mg | C10: 0.56 mg | D10: 0.7 mL; 0.8 mg/mL | E10: 0.40 mL | F10: 40 U | H10: 17 to <22 kg | I10: 0.32 mg | J10: 0.56 mg/vial | K10: 0.8 mg/mL | L10: 0.4 mL | M10: 40 U | N10: Unchanged | O10: Same dose and volume.
A11: 22–32 | B11: 0.40 mg | C11: 0.56 mg | D11: 0.7 mL; 0.8 mg/mL | E11: 0.50 mL | F11: 50 U | H11: 22 to <33 kg | I11: 0.4 mg | J11: 0.56 mg/vial | K11: 0.8 mg/mL | L11: 0.5 mL | M11: 50 U | N11: Unchanged | O11: Same dose and volume.
A12: 33–43 | B12: 0.50 mg | C12: 1.2 mg | D12: 0.6 mL; 2 mg/mL | E12: 0.25 mL | F12: 25 U | H12: 33 to <44 kg | I12: 0.5 mg | J12: 1.2 mg/vial | K12: 2 mg/mL | L12: 0.25 mL | M12: 25 U | N12: Unchanged | O12: Same dose and volume.
A13: 44–59 | B13: 0.60 mg | C13: 1.2 mg | D13: 0.6 mL; 2 mg/mL | E13: 0.30 mL | F13: 30 U | H13: 44 to <60 kg | I13: 0.6 mg | J13: 1.2 mg/vial | K13: 2 mg/mL | L13: 0.3 mL | M13: 30 U | N13: Unchanged | O13: Same dose and volume.
A14: 60–89 | B14: 0.70 mg | C14: 1.2 mg | D14: 0.6 mL; 2 mg/mL | E14: 0.35 mL | F14: 35 U | H14: 60 to <90 kg | I14: 0.7 mg | J14: 1.2 mg/vial | K14: 2 mg/mL | L14: 0.35 mL | M14: 35 U | N14: Unchanged | O14: Same dose and volume.
A15: ≥ 90 | B15: 0.80 mg | C15: 1.2 mg | D15: 0.6 mL; 2 mg/mL | E15: 0.40 mL | F15: 40 U | H15: ≥ 90 kg | I15: 0.8 mg | J15: 1.2 mg/vial | K15: 2 mg/mL | L15: 0.4 mL | M15: 40 U | N15: Unchanged | O15: Same dose and volume.
A17: Key points
A18: • The 2024 table started at 10 kg, although the guideline allowed treatment from 4 months. Infants under 10 kg had no listed dose. The update adds 4 kg, 5 kg, 6–7 kg and 8–11 kg bands.
A19: • For 10 kg and above, the dose, vial and injection volume are the same in both versions. Only the way the bands are written has changed.
A20: • Added in the update: solvent volume for reconstitution (0.5 / 0.7 / 0.6 mL). Dropped: the 'Frequency of dosing' column (once daily in both).
A21: • The updated draft still shows the old 2024 table (in red) above the new one. Remove it before sign-off so there's only one dosing table (medication-safety point).

Sheet Monitoring Schedule
A1: Follow-up schedule: updated 5.5.5 vs 2024 appendix 11.20
A2: Updated = new age-stratified table (section 5.5.5). Old = 2024 timing table in appendix 11.20 (Day 0 / Month 1 / Month 3 / every 6 months / annually).
A3: UPDATED (5.5.5) | F3: OLD (2024, appendix 11.20) | G3: COMPARISON
A4: Assessment | B4: 0–2 years | C4: Over 2 years to growth-plate closure | D4: Refs | F4: Old timing (all ages) | G4: Status | H4: Comment
A5: Visit interval | B5: Every 3 months | C5: Every 6 months | D5: 6,12,13 | F5: Day 0, Month 1, Month 3, then every 6 months | G5: Modified | H5: Infants are now seen every 3 months throughout, not every 6 months after month 3. The Month 1 visit is no longer listed.
A6: Length/height and weight | B6: Every visit | C6: Every visit (every 6 months) | D6: 12,13,17 | F6: Anthropometrics: Day 0 and every 6 months | G6: Modified | H6: More frequent for 0–2 years. Weight is now named explicitly (needed for the dose check).
A7: Head circumference | B7: Every visit | C7: Every visit up to about 5 years; then not routine | D7: 12,13 | F7: Not specified | G7: New | H7: New item. Linked to the foramen magnum / hydrocephalus risk in young children.
A8: Annualized growth velocity | B8: From month 6, then each visit | C8: Every visit; below 1.5 cm/year triggers stop review | D8: 6,12,17 | F8: Every 6 months | G8: Modified | H8: Starts from month 6. A low AGV now triggers a stop review – it is not an automatic stop (see 5.4).
A9: Upper-to-lower segment ratio | B9: Every 6–12 months | C9: Every 6 months | D9: 17 | F9: Part of anthropometrics (upper & lower arm segment): Day 0 and every 6 months | G9: Modified | H9: Now its own line with an age-specific interval.
A10: Dose check against weight band | B10: Every 3 months | C10: Every visit (every 6 months) | D10: 6,13 | F10: Not specified | G10: New | H10: New. Matches the 5.3.5 rule (weight-band review every 3–6 months).
A11: Neurological examination | B11: Every visit | C11: Every visit | D11: 12,13 | F11: Symptoms (headaches, vision changes, joint pain): Month 1, Month 3, every 6 months | G11: Modified | H11: Symptom check becomes a formal neuro exam at every visit.
A12: Sleep symptom review | B12: Every visit; repeat sleep study if symptoms | C12: Every visit; sleep study if symptoms | D12: 12,19 | F12: Not specified | G12: New | H12: New. Ties in with routine polysomnography in infancy (5.2).
A13: Adverse events, injection sites, hypotension symptoms | B13: Every visit | C13: Every visit | D13: 6,16,17 | F13: Review adverse events: every 6 months | G13: Modified | H13: Every visit, so every 3 months for infants. Injection sites and hypotension now named explicitly.
A14: Tanner stage | B14: No | C14: From about 8 years, every 6 months | D14: 13 | F14: Day 0 and every 6 months (all ages) | G14: Modified | H14: No longer done in young children. Starts from about 8 years.
A15: Skeletal survey (growth plates and bone age) | B15: Annually | C15: Annually; stop treatment if growth plates closed (see 5.4) | D15: 2024 CPG | F15: X-ray and bone age: Day 0 and annually | G15: Unchanged | H15: Same annual frequency, carried over from the 2024 CPG.
A16: Parental height | B16: — | C16: — | F16: Day 0 | G16: Removed | H16: Not in the new table, but still listed under 5.5.1 (treatment-informing). Only a baseline item in both versions.
A17: Vitamin D level | B17: — | C17: — | F17: Day 0 and annually | G17: Removed | H17: Not in the new table. Still listed under 5.5.1, but without timing. Suggest adding 'annually' to 5.5.5 if the yearly check should stay.
A18: Concomitant / new medications | B18: — | C18: — | F18: Every 6 months | G18: Removed | H18: Only covered at baseline (5.5.4) now. Suggest adding back to the follow-up table.
A19: Discussion of other interventions | B19: — | C19: — | F19: Every 6 months | G19: Removed | H19: Still listed under 5.5.3, but no timing in the new table.

Sheet References
A1: Section 9 – Reference list: updated vs 2024
A2: Lined up by source. Updated list has 19 references; 2024 list had 11.
A3: UPDATED | D3: OLD (2024) | F3: COMPARISON
A4: # | B4: Reference (updated) | D4: # | E4: Reference (2024) | F4: Status | G4: Comment / where cited
A5: 1 | B5: Genetics of Achondroplasia. Updated Jan 10, 2022. Defendi GL; Chief Editor: Maria D. Medscape. https://emedicine.medscape.com/article/941280-overview | D5: 1 | E5: Genetics of Achondroplasia. Updated Jan 10, 2022. Defendi GL; Chief Editor: Maria D. Medscape. https://emedicine.medscape.com/article/941280-overview | F5: Unchanged | G5: Cited in Introduction.
A6: 2 | B6: Epidemiology of achondroplasia: A population-based study in Europe. Am J Med Genet A. 2019;179(9):1791-1798. doi:10.1002/ajmg.a.61289. https://pubmed.ncbi.nlm.nih.gov/31294928/ | D6: 2 | E6: Epidemiology of achondroplasia: A population-based study in Europe. Am J Med Genet A. 2019;179(9):1791-1798. doi:10.1002/ajmg.a.61289. https://pubmed.ncbi.nlm.nih.gov/31294928/ | F6: Unchanged | G6: Cited in Introduction and 2.1.
A7: 3 | B7: Legare JM. Achondroplasia. 1998 Oct 12 [Updated 2023 May 11]. In: Adam MP, et al., editors. GeneReviews®. Seattle (WA): University of Washington; 1993-2023. https://www.ncbi.nlm.nih.gov/books/NBK1152/ | D7: 3 | E7: Legare JM. Achondroplasia. 1998 Oct 12 [Updated 2023 May 11]. In: Adam MP, et al., editors. GeneReviews®. Seattle (WA): University of Washington; 1993-2023. https://www.ncbi.nlm.nih.gov/books/NBK1152/ | F7: Unchanged | G7: Cited in Introduction and 2.1.
A8: 4 | B8: The first and only therapy approved to increase linear growth in children with achondroplasia aged 5 years and over with open growth plates. https://www.biomarin.com/our-treatments/products/voxzogo/ | D8: 4 | E8: The first and only therapy approved to increase linear growth in children with achondroplasia aged 5 years and over with open growth plates. https://www.biomarin.com/our-treatments/products/voxzogo/ | F8: Unchanged | G8: Still listed, but no longer cited anywhere in the updated text. It also describes the old '5 years and over' indication. Suggest removing it or marking it as historical.
A9: 5 | B9: European Commission Approves BioMarin's VOXZOGO® (vosoritide) for the Treatment of Children with Achondroplasia from Age 2 Until Growth Plates Close. (PR Newswire) | D9: 5 | E9: European Commission Approves BioMarin's VOXZOGO® (vosoritide) for the Treatment of Children with Achondroplasia from Age 2 Until Growth Plates Close. (PR Newswire) | F9: Unchanged | G9: Still listed, but no longer cited (5.3.1 now cites ref 6 for the EU label). Describes the old 'from age 2' indication. Suggest removing it.
A10: 6 | B10: SUMMARY OF PRODUCT CHARACTERISTICS: Voxzogo (vosoritide) 0.4 mg, 0.56 mg and 1.2 mg powder and solvent for solution for injection. BioMarin International Limited; European Medicines Agency. Date of revision of the text: 10/2023. https://www.ema.europa.eu/en/medicines/human/EPAR/voxzogo | D10: 6 | E10: SUMMARY OF PRODUCT CHARACTERISTICS. https://www.biomarin.com/our-treatments/products/voxzogo/ | F10: Modified | G10: Now a full, traceable EMA citation with revision date. It's the main source for 5.3.1, 5.3.4, 5.3.5, 5.4, 5.5.4–5.5.5 and Table 12.1. (In 2024, in-text '(6)' was used for the FDA statement.)
A11: — | B11: Removed | D11: 7 | E11: The first and only therapy approved to increase linear growth in children with achondroplasia aged 5 years and over with open growth plates. https://www.biomarin.com/our-treatments/products/voxzogo/#:~:text=... | F11: Removed | G11: Duplicate of ref 4 (same BioMarin page). Rightly removed.
A12: 7 | B12: Growth charts for Australian children with achondroplasia. Am J Med Genet A. 2017;173(8):2189-2200. doi:10.1002/ajmg.a.38312 | D12: 8 | E12: Growth charts for Australian children with achondroplasia. Am J Med Genet A. 2017;173(8):2189-2200. doi:10.1002/ajmg.a.38312 | F12: Renumbered | G12: 8 → 7. Supports the growth charts in the appendix.
A13: 8 | B13: Pauli RM. Achondroplasia: a comprehensive clinical review. Orphanet J Rare Dis. 2019;14:1. https://ojrd.biomedcentral.com/articles/10.1186/s13023-018-0972-6 | D13: 9 | E13: Pauli RM. Achondroplasia: a comprehensive clinical review. Orphanet J Rare Dis. 2019;14:1. https://ojrd.biomedcentral.com/articles/10.1186/s13023-018-0972-6 | F13: Renumbered | G13: 9 → 8.
A14: 9 | B14: Clinical Practice Guidelines for Achondroplasia. Clin Pediatr Endocrinol. 2020;29(1):25–42. PMC6958518 | D14: 10 | E14: Clinical Practice Guidelines for Achondroplasia. Clin Pediatr Endocrinol. 2020;29(1):25–42. PMC6958518 | F14: Renumbered | G14: 10 → 9.
A15: 10 | B15: https://www.chegg.com/learn/topic/achondroplastic-dwarfism | D15: 11 | E15: https://www.chegg.com/learn/topic/achondroplastic-dwarfism | F15: Renumbered | G15: 11 → 10. This is a general education website, not a peer-reviewed source. Consider replacing it.
... A24: 19 | B24: Guerdile MJ, et al. Sleep-disordered breathing in children with achondroplasia: 17 years' experience from a multidisciplinary team. J Pediatr Genet. 2025;14(1). doi:10.1055/s-0044-1791787 | D24: — | E24: — Not addressed in this version — | F24: New | G24: Cited in 5.5.5 (sleep symptom review).
